Workbook
Name 주택특징: t!$BD$2:$BD$9

Sheet 요약
B2: 주택1 | C2: 주택2 | D2: 주택3 | E2: 주택4 | F2: 건축물 | G2: 토지1 | H2: 토지2 | J2: (15% 상승 가정) | K2: =공동보유!B4 -> 3주택
A3: 주소 | B3: =HLOOKUP(B$2,기초!$C$5:$I$16,MATCH($A3,기초!$A$5:$A$16,0),0) -> 서현동 | C3: =HLOOKUP(C$2,기초!$C$5:$I$16,MATCH($A3,기초!$A$5:$A$16,0),0) -> 잠원동 | D3: =HLOOKUP(D$2,기초!$C$5:$I$16,MATCH($A3,기초!$A$5:$A$16,0),0) -> 수유동 | E3: =HLOOKUP(E$2,기초!$C$5:$I$16,MATCH($A3,기초!$A$5:$A$16,0),0) -> 장위동 | F3: =HLOOKUP(F$2,기초!$C$5:$I$16,MATCH($A3,기초!$A$5:$A$16,0),0) -> 0 | G3: =HLOOKUP(G$2,기초!$C$5:$I$16,MATCH($A3,기초!$A$5:$A$16,0),0) -> 0 | H3: =HLOOKUP(H$2,기초!$C$5:$I$16,MATCH($A3,기초!$A$5:$A$16,0),0) -> 0 | J3: *보유세(현행 보유) | K3: 2026년 | L3: 2027년 | M3: 2028년 | N3: 2029년 | O3: 2030년
A4: 감정평가 | B4: =HLOOKUP(B$2,기초!$C$5:$I$16,MATCH($A4,기초!$A$5:$A$16,0),0) -> 4000000000 | C4: =HLOOKUP(C$2,기초!$C$5:$I$16,MATCH($A4,기초!$A$5:$A$16,0),0) -> 1300000000 | D4: =HLOOKUP(D$2,기초!$C$5:$I$16,MATCH($A4,기초!$A$5:$A$16,0),0) -> 2000000000 | E4: =HLOOKUP(E$2,기초!$C$5:$I$16,MATCH($A4,기초!$A$5:$A$16,0),0) -> 2500000000 | F4: =HLOOKUP(F$2,기초!$C$5:$I$16,MATCH($A4,기초!$A$5:$A$16,0),0) -> 0 | G4: =HLOOKUP(G$2,기초!$C$5:$I$16,MATCH($A4,기초!$A$5:$A$16,0),0) -> 0 | H4: =HLOOKUP(H$2,기초!$C$5:$I$16,MATCH($A4,기초!$A$5:$A$16,0),0) -> 0 | J4: 재산세 소계
A5: 취득가액 | B5: =HLOOKUP(B$2,기초!$C$5:$I$16,MATCH($A5,기초!$A$5:$A$16,0),0) -> 1000000000 | C5: =HLOOKUP(C$2,기초!$C$5:$I$16,MATCH($A5,기초!$A$5:$A$16,0),0) -> 700000000 | D5: =HLOOKUP(D$2,기초!$C$5:$I$16,MATCH($A5,기초!$A$5:$A$16,0),0) -> 1500000000 | E5: =HLOOKUP(E$2,기초!$C$5:$I$16,MATCH($A5,기초!$A$5:$A$16,0),0) -> 2000000000 | F5: =HLOOKUP(F$2,기초!$C$5:$I$16,MATCH($A5,기초!$A$5:$A$16,0),0) -> 0 | G5: =HLOOKUP(G$2,기초!$C$5:$I$16,MATCH($A5,기초!$A$5:$A$16,0),0) -> 0 | H5: =HLOOKUP(H$2,기초!$C$5:$I$16,MATCH($A5,기초!$A$5:$A$16,0),0) -> 0 | J5: 종합부동산세 소계
A6: 시가 | J6: 합계 | K6: =SUM(K4:K5) -> 0 | L6: =SUM(L4:L5) -> 0 | M6: =SUM(M4:M5) -> 0 | N6: =SUM(N4:N5) -> 0 | O6: =SUM(O4:O5) -> 0
A8: 양도소득세 | J8: *보유세(2026년 양도/증여 후) | K8: 2026년 | L8: 2027년 | M8: 2028년 | N8: 2029년 | O8: 2030년
A9: 2026년 비과세 | B9: =양도!G25 -> 1.55166e+08 | J9: 재산세 소계
A10: 2027년 비과세 | B10: =양도!M25 -> 1.55166e+08 | J10: 종합부동산세 소계
A11: 2028년 비과세 | B11: =양도!S25 -> 155166000 | J11: 합계 | K11: =SUM(K9:K10) -> 0 | L11: =SUM(L9:L10) -> 0 | M11: =SUM(M9:M10) -> 0 | N11: =SUM(N9:N10) -> 0 | O11: =SUM(O9:O10) -> 0
A12: 일반과세 | B12: =양도!A25 -> 1.55166e+08
A13: 2주택 중과세 | B13: =양도!C25 -> 2070678500 | J13: *보유세(2027년 6/1 이후 양도/증여) | K13: 2026년 | L13: 2027년 | M13: 2028년 | N13: 2029년 | O13: 2030년
A14: 3주택 중과세 | B14: =양도!D25 -> 2400403500 | J14: 재산세 소계
J15: 종합부동산세 소계
A16: 저가양수도 | J16: 합계 | K16: =K6 -> 0 | L16: =L6 -> 0 | M16: =SUM(M14:M15) -> 0 | N16: =SUM(N14:N15) -> 0 | O16: =SUM(O14:O15) -> 0
A17: 2026년 비과세
A18: 2027년 비과세 | J18: *자녀의 보유세 | K18: 2026년 | L18: 2027년 | M18: 2028년 | N18: 2029년 | O18: 2030년
A19: 2028년 비과세 | J19: 재산세 소계
A20: 일반과세 | J20: 종합부동산세 소계
A21: 2주택 중과세 | J21: 합계 | L21: =SUM(L19:L20) -> 0 | M21: =SUM(M19:M20) -> 0 | N21: =SUM(N19:N20) -> 0 | O21: =SUM(O19:O20) -> 0
A22: 3주택 중과세
A23: 필요자금(3억 or 30% 차감금액) | B23: =저가양수도!C20 -> 3401000000
A24: 매매취득세 | B24: =저가양수도!C41 -> 132000000
A25: 저가양수도 합계 | B25: =SUM(B23:B24) -> 3533000000
A27: 순수증여 | B27: =증여!B4 -> 홍상수
A28: 증여세(자녀) | B28: =증여!B22 -> 1515000000
A29: 증여취득세(자녀) | B29: =증여!B26 -> 187860000
A30: 증여 합계 | B30: =SUM(B28:B29) -> 1702860000
A33: 상속재산가액 | B33: =상속!B3 -> 10050000000
A35: 상속세 | B35: =상속!B15 -> 3475000000
A36: 상속취득세 | B36: =상속!B24 -> 256780000
A37: 상속 합계 | B37: =SUM(B35:B36) -> 3731780000

Sheet 기초
A1: 소유자1 | B1: 홍길동 | F1: 확인 후 기입 | G1: 수기기입가능 | H1: 필수선택
A2: 연령 | B2: 55 | F2: 해당없음 | G2: 필수기입 | H2: 개정안 | I2: 개정(미정)
A3: 주택수 | B3: 2 | C3: 2주택
A5: 재산구분 | C5: 주택1 | D5: 주택2 | E5: 주택3 | F5: 주택4 | G5: 건축물 | H5: 토지1 | I5: 토지2 | J5: 금융재산/채무 | K5: 보험 | L5: 근로소득 | M5: 차량 | N5: 회원권 | O5: 기타재산1 | P5: 기타재산2 | Q5: 기타재산3 | R5: 그 외 채무
A6: 주택면적 | C6: 국평 | D6: 국평 | E6: 국평 | F6: 국평
A7: 지역 | C7: 조정대상지역 | D7: 조정대상지역 | E7: 일반지역 | F7: 일반지역
A8: 주소 | C8: 서현동 | D8: 잠원동 | E8: 수유동 | F8: 장위동
A9: 감정평가 | C9: 4000000000 | D9: 1300000000 | E9: 2000000000 | F9: 2500000000 | J9: 900000000
A10: 보충적평가액
A11: 채무액
A12: 시가표준액 | C12: 3500000000 | D12: 1150000000 | E12: 1.725e+09 | F12: 2300000000
A13: 취득가액 | C13: 1000000000 | D13: 700000000 | E13: 1500000000 | F13: 2000000000
A14: 보유기간 | C14: 15 | D14: =2026-2022 -> 4 | E14: 5 | F14: 6
A15: 거주기간 | C15: 10 | D15: 4 | E15: 4 | F15: 3
A16: 보유지분 | C16: 1 | D16: 0.5 | E16: 1 | F16: 1
A17: 상속재산가액 | B17: =SUM(C17:R17) -> 10050000000 | C17: =(MIN(C$9:C$10)-C$11)*C16 -> 4000000000 | D17: =(MIN(D9:D10)-D11)*D16 -> 650000000 | E17: =(MIN(E9:E10)-E11)*E16 -> 2000000000 | F17: =(MIN(F9:F10)-F11)*F16 -> 2500000000 | G17: =(MIN(G9:G10)-G11)*G16 -> 0 | H17: =(MIN(H9:H10)-H11)*H16 -> 0 | I17: =(MIN(I9:I10)-I11)*I16 -> 0 | J17: =(MIN(J9:J10)-J11) -> 900000000 | K17: =(MIN(K9:K10)-K11) -> 0 | L17: =(MIN(L9:L10)-L11) -> 0 | M17: =(MIN(M9:M10)-M11) -> 0 | N17: =(MIN(N9:N10)-N11) -> 0 | O17: =(MIN(O9:O10)-O11) -> 0 | P17: =(MIN(P9:P10)-P11) -> 0 | Q17: =(MIN(Q9:Q10)-Q11) -> 0 | R17: =(MIN(R9:R10)-R11) -> 0
A21: 대상1 | B21: 성춘향
A22: 관계 | B22: 배우자
A23: 연령 | B23: =2026-1987 -> 39
A24: 주택수 | B24: 1 | C24: 주택
A25: 상속지분 | B25: =IF(B22="배우자",1.5,IF(B22="직계존비속",1,0)) -> 1.5
A26: 상증공제 | C26: =C$5 -> 주택1 | D26: =D$5 -> 주택2 | E26: =E$5 -> 주택3 | F26: =F$5 -> 주택4 | G26: =G$5 -> 건축물 | H26: =H$5 -> 토지1 | I26: =I$5 -> 토지2 | S26: 사전증여재산 | T26: 기증여산출세액 | U26: 증여시점
A27: 취득가액 | D27: 300000000
A28: 보유기간 | D28: 3
A29: 거주기간 | D29: 2
A30: 보유지분 | D30: 0.5
A31: 소계 | B31: =SUM(C31:R31) -> 650000000 | C31: =(MIN(C$9:C$10)-C$11)*C30 -> 0 | D31: =(MIN(D$9:D$10)-D$11)*D30 -> 650000000 | E31: =(MIN(E$9:E$10)-E$11)*E30 -> 0 | F31: =(MIN(F$9:F$10)-F$11)*F30 -> 0 | G31: =(MIN(G$9:G$10)-G$11)*G30 -> 0 | H31: =(MIN(H$9:H$10)-H$11)*H30 -> 0 | I31: =(MIN(I$9:I$10)-I$11)*I30 -> 0 | S31: 600000000 | T31: 0 | U31: 45658
A34: 대상2 | B34: 홍상수
A35: 관계 | B35: 직계존비속 | C35: 자녀
A36: 연령 | B36: 15
A37: 주택수 | B37: 0 | C37: 1세대1주택
A38: 상속지분 | B38: =IF(B35="배우자",1.5,IF(B35="직계존비속",1,0)) -> 1
A39: 상증공제 | B39: 동거 | C39: =C$5 -> 주택1 | D39: =D$5 -> 주택2 | E39: =E$5 -> 주택3 | F39: =F$5 -> 주택4 | G39: =G$5 -> 건축물 | H39: =H$5 -> 토지1 | I39: =I$5 -> 토지2 | S39: 사전증여재산 | T39: 기증여산출세액 | U39: 증여시점
A40: 취득가액
A41: 보유기간
A42: 거주기간
A43: 보유지분
A44: 소계 | B44: =SUM(C44:R44) -> 0 | C44: =(MIN(C$9:C$10)-C$11)*C43 -> 0 | D44: =(MIN(D$9:D$10)-D$11)*D43 -> 0 | E44: =(MIN(E$9:E$10)-E$11)*E43 -> 0 | F44: =(MIN(F$9:F$10)-F$11)*F43 -> 0 | G44: =(MIN(G$9:G$10)-G$11)*G43 -> 0 | H44: =(MIN(H$9:H$10)-H$11)*H43 -> 0 | I44: =(MIN(I$9:I$10)-I$11)*I43 -> 0 | S44: 600000000 | T44: 0 | U44: 45658
A47: 대상3 | B47: (이름)
A48: 관계 | B48: 직계존비속 | C48: 자녀
...

Sheet 공동보유
B1: 소유자1 | C1: 소유자2 | I1: *공동명의 상태에서 새 기본공제 산식의 ‘거주주택가액’을 지분상당액으로 볼지에 관한 별도 예규·시행규칙은 아직 나오지 않은 입법예고 단계
A2: 소유자 | B2: =기초!$B$1 -> 홍길동 | C2: 성춘향 | I2: *조정대상지역 보유자(1세대1주택 아님)와 3주택 이상 세율 적용자는 2027년에 특히 구분할 것
A3: 주택수 | B3: 4 | C3: =INDIRECT("기초!b"&(MATCH(C$2,기초!$B:$B,0)+3)) -> 1 | E3: 2026 | F3: 소유자1 | G3: 소유자2 | M3: =E3+1 -> 2027 | N3: 소유자1 | O3: 소유자2 | U3: =M3+1 -> 2028 | V3: 소유자1 | W3: 소유자2 | AC3: =U3+1 -> 2029 | AD3: 소유자1 | AE3: 소유자2 | AK3: =AC3+1 -> 2030 | AL3: 소유자1 | AM3: 소유자2
A4: 개정세법 분류 | B4: =IF(AND(B5="1세대1주택",LEFT(B6,2)="주택"),"거주용1주택",IF(AND(B5="1세대1주택",B6="비거주"),"비거주1주택",IF(AND(B3<=2,B7<>"조정대상지역"),"비거주1주택","3주택"))) -> 3주택 | C4: =IF(AND(C5="1세대1주택",LEFT(C6,2)="주택"),"거주용1주택",IF(AND(C5="1세대1주택",C6="비거주"),"비거주1주택",IF(AND(C3<=2,C7<>"조정대상지역"),"비거주1주택","3주택"))) -> 3주택 | E4: 재산세납부액 | F4: =SUMPRODUCT(B20:G20,B35:G35) -> 23505600 | G4: =SUMPRODUCT(B20:G20,B68:G68) -> 1216950 | M4: 재산세납부액 | N4: =SUMPRODUCT(J20:O20,J35:O35) -> 29218590 | O4: =SUMPRODUCT(J20:O20,J68:O68) -> 1883992.5 | U4: 재산세납부액 | V4: =SUMPRODUCT(R20:W20,R35:W35) -> 32005800 | W4: =SUMPRODUCT(R20:W20,R68:W68) -> 2081850 | AC4: 재산세납부액 | AD4: =SUMPRODUCT(Z20:AE20,Z35:AE35) -> 33998278 | AE4: =SUMPRODUCT(Z20:AE20,Z68:AE68) -> 2223291.4 | AK4: 재산세납부액 | AL4: =SUMPRODUCT(AH20:AM20,AH35:AM35) -> 38999260 | AM4: =SUMPRODUCT(AH20:AM20,AH68:AM68) -> 2479115.8
A5: 1세대1주택 여부 | B5: 해당없음 | C5: =INDIRECT("기초!c"&(MATCH(C$2,기초!$B:$B,0)+3)) -> 주택 | E5: 종부세납부액 | F5: =B61 -> 98538727 | G5: =B94 -> 0 | M5: 종부세납부액 | N5: =HLOOKUP($B$4,$J$46:$L$61,16,0) -> 1.7235048e+08 | O5: =HLOOKUP($C$4,$J$79:$L$94,16,0) -> 437724 | U5: 종부세납부액 | V5: =HLOOKUP($B$4,$R$46:$T$61,16,0) -> 2.1033027e+08 | W5: =HLOOKUP($C$4,$R$79:$T$94,16,0) -> 453955.86 | AC5: 종부세납부액 | AD5: =HLOOKUP($B$4,$Z$46:$AB$61,16,0) -> 2.6269135e+08 | AE5: =HLOOKUP($C$4,$Z$79:$AB$94,16,0) -> 782766.99 | AK5: 종부세납부액 | AL5: =HLOOKUP($B$4,$AH$46:$AJ$61,16,0) -> 2.859224e+08 | AM5: =HLOOKUP($C$4,$AH$79:$AJ$94,16,0) -> 698480.9
A6: 거주주택 | B6: 주택1 | C6: 주택1 | E6: 소계 | F6: =F4+F5 -> 1.2204433e+08 | G6: =G4+G5 -> 1216950 | M6: 보유세 합계 | N6: =N4+N5 -> 2.0156907e+08 | O6: =O4+O5 -> 2321716.5 | U6: 보유세 합계 | V6: =V4+V5 -> 2.4233607e+08 | W6: =W4+W5 -> 2535805.9 | AC6: 보유세 합계 | AD6: =AD4+AD5 -> 2.9668963e+08 | AE6: =AE4+AE5 -> 3006058.4 | AK6: 보유세 합계 | AL6: =AL4+AL5 -> 3.2492166e+08 | AM6: =AM4+AM5 -> 3177596.7
A7: 지역 | B7: =HLOOKUP(B$6,기초!$C$5:$I$16,MATCH($A7,기초!$A$5:$A$16,0),0) -> 조정대상지역 | C7: =HLOOKUP(C$6,기초!$C$5:$I$16,MATCH($A7,기초!$A$5:$A$16,0),0) -> 조정대상지역
I8: 예상증가율(%) | J8: 0.15 | K8: 0.15 | L8: 0.15 | M8: 0.15 | O8: 0 | Q8: 예상증가율(%) | R8: 0 | S8: 0 | T8: 0 | U8: 0 | W8: 0 | Y8: 예상증가율(%) | Z8: 0.15 | AA8: 0.15 | AB8: 0.15 | AC8: 0.15 | AE8: 0.15 | AG8: 예상증가율(%) | AH8: 0.1 | AI8: 0.01 | AJ8: 0.03 | AK8: 0.05 | AM8: 0.15
A9: 2026 | B9: 주택1 | C9: 주택2 | D9: 주택3 | E9: 주택4 | F9: 주택소계 | G9: 건축물 | I9: =A9+1 -> 2027 | J9: 주택1 | K9: 주택2 | L9: 주택3 | M9: 주택4 | N9: 주택소계 | O9: 건축물 | Q9: =I9+1 -> 2028 | R9: 주택1 | S9: 주택2 | T9: 주택3 | U9: 주택4 | V9: 주택소계 | W9: 건축물 | Y9: =Q9+1 -> 2029 | Z9: 주택1 | AA9: 주택2 | AB9: 주택3 | AC9: 주택4 | AD9: 주택소계 | AE9: 건축물 | AG9: =Y9+1 -> 2030 | AH9: 주택1 | AI9: 주택2 | AJ9: 주택3 | AK9: 주택4 | AL9: 주택소계 | AM9: 건축물
B10: =IF(OR($B$5="1세대1주택"),"1세대1주택","주택") -> 주택 | C10: =IF(OR($B$5="1세대1주택"),"1세대1주택","주택") -> 주택 | D10: =IF(OR($B$5="1세대1주택"),"1세대1주택","주택") -> 주택 | E10: =IF(OR($B$5="1세대1주택"),"1세대1주택","주택") -> 주택 | F10: 주택 | G10: 건물 | J10: =B$10 -> 주택 | K10: =C$10 -> 주택 | L10: =D$10 -> 주택 | M10: =E$10 -> 주택 | N10: 주택 | O10: 건물 | R10: =J$10 -> 주택 | S10: =K$10 -> 주택 | T10: =L$10 -> 주택 | U10: =M$10 -> 주택 | V10: 주택 | W10: 건물 | Z10: =R$10 -> 주택 | AA10: =S$10 -> 주택 | AB10: =T$10 -> 주택 | AC10: =U$10 -> 주택 | AD10: 주택 | AE10: 건물 | AH10: =Z$10 -> 주택 | AI10: =AA$10 -> 주택 | AJ10: =AB$10 -> 주택 | AK10: =AC$10 -> 주택 | AL10: 주택 | AM10: 건물
A11: 시가표준액 | B11: =HLOOKUP(B$9,기초!$C$5:$I$16,MATCH($A11,기초!$A$5:$A$16,0),0) -> 3500000000 | C11: =HLOOKUP(C$9,기초!$C$5:$I$16,MATCH($A11,기초!$A$5:$A$16,0),0) -> 1150000000 | D11: =HLOOKUP(D$9,기초!$C$5:$I$16,MATCH($A11,기초!$A$5:$A$16,0),0) -> 1.725e+09 | E11: =HLOOKUP(E$9,기초!$C$5:$I$16,MATCH($A11,기초!$A$5:$A$16,0),0) -> 2300000000 | F11: =SUM(B11:E11) -> 8675000000 | G11: =HLOOKUP(G$9,[1]기초!$C$5:$I$16,MATCH($A11,[1]기초!$A$5:$A$16,0),0) -> 0 | I11: 시가표준액(예상) | J11: =B11*(1+J8) -> 4.025e+09 | K11: =C11*(1+K8) -> 1322500000 | L11: =D11*(1+L8) -> 1.98375e+09 | M11: =E11*(1+M8) -> 2645000000 | N11: =SUM(J11:M11) -> 9976250000 | O11: =G11*(1+O8) -> 0 | Q11: 시가표준액(예상) | R11: =J11*(1+R8) -> 4.025e+09 | S11: =K11*(1+S8) -> 1322500000 | T11: =L11*(1+T8) -> 1.98375e+09 | U11: =M11*(1+U8) -> 2645000000 | V11: =SUM(R11:U11) -> 9976250000 | W11: =O11*(1+W8) -> 0 | Y11: 시가표준액(예상) | Z11: =R11*(1+Z8) -> 4.62875e+09 | AA11: =S11*(1+AA8) -> 1520875000 | AB11: =T11*(1+AB8) -> 2.2813125e+09 | AC11: =U11*(1+AC8) -> 3041750000 | AD11: =SUM(Z11:AC11) -> 1.1472687e+10 | AE11: =W11*(1+AE8) -> 0 | AG11: 시가표준액(예상) | AH11: =Z11*(1+AH8) -> 5.091625e+09 | AI11: =AA11*(1+AI8) -> 1536083750 | AJ11: =AB11*(1+AJ8) -> 2.3497519e+09 | AK11: =AC11*(1+AK8) -> 3193837500 | AL11: =SUM(AH11:AK11) -> 1.2171298e+10 | AM11: =AE11*(1+AM8) -> 0
A12: 공정시장가액비율 | B12: =IF(B$10="1세대1주택", IF(B11<=3*10^8,43%, IF(B11<=6*10^8,44%, 45%)), VLOOKUP(B$10,t!$H$3:$I$9,2,0)) -> 0.6 | C12: =IF(C$10="1세대1주택", IF(C11<=3*10^8,43%, IF(C11<=6*10^8,44%, 45%)), VLOOKUP(C$10,t!$H$3:$I$9,2,0)) -> 0.6 | D12: =IF(D$10="1세대1주택", IF(D11<=3*10^8,43%, IF(D11<=6*10^8,44%, 45%)), VLOOKUP(D$10,t!$H$3:$I$9,2,0)) -> 0.6 | E12: =IF(E$10="1세대1주택", IF(E11<=3*10^8,43%, IF(E11<=6*10^8,44%, 45%)), VLOOKUP(E$10,t!$H$3:$I$9,2,0)) -> 0.6 | F12: =IF(B10="1세대1주택",B12,60%) -> 0.6 | G12: =IF(G10="1세대1주택", IF(G11<=3*10^8,43%, IF(G11<=6*10^8,44%, 45%)), VLOOKUP(G10,t!$H$3:$I$9,2,0)) -> 0.7 | I12: 공정시장가액비율 | J12: =IF(J$10="1세대1주택", IF(J11<=3*10^8,43%, IF(J11<=6*10^8,44%, 45%)), VLOOKUP(J$10,t!$H$3:$I$9,2,0)) -> 0.6 | K12: =IF(K$10="1세대1주택", IF(K11<=3*10^8,43%, IF(K11<=6*10^8,44%, 45%)), VLOOKUP(K$10,t!$H$3:$I$9,2,0)) -> 0.6 | L12: =IF(L$10="1세대1주택", IF(L11<=3*10^8,43%, IF(L11<=6*10^8,44%, 45%)), VLOOKUP(L$10,t!$H$3:$I$9,2,0)) -> 0.6 | M12: =IF(M$10="1세대1주택", IF(M11<=3*10^8,43%, IF(M11<=6*10^8,44%, 45%)), VLOOKUP(M$10,t!$H$3:$I$9,2,0)) -> 0.6 | N12: =IF(J10="1세대1주택",J12,60%) -> 0.6 | O12: =IF(O10="1세대1주택", IF(O11<=3*10^8,43%, IF(O11<=6*10^8,44%, 45%)), VLOOKUP(O10,t!$H$3:$I$9,2,0)) -> 0.7 | Q12: 공정시장가액비율 | R12: =IF(R$10="1세대1주택", IF(R11<=3*10^8,43%, IF(R11<=6*10^8,44%, 45%)), VLOOKUP(R$10,t!$H$3:$I$9,2,0)) -> 0.6 | S12: =IF(S$10="1세대1주택", IF(S11<=3*10^8,43%, IF(S11<=6*10^8,44%, 45%)), VLOOKUP(S$10,t!$H$3:$I$9,2,0)) -> 0.6 | T12: =IF(T$10="1세대1주택", IF(T11<=3*10^8,43%, IF(T11<=6*10^8,44%, 45%)), VLOOKUP(T$10,t!$H$3:$I$9,2,0)) -> 0.6 | U12: =IF(U$10="1세대1주택", IF(U11<=3*10^8,43%, IF(U11<=6*10^8,44%, 45%)), VLOOKUP(U$10,t!$H$3:$I$9,2,0)) -> 0.6 | V12: =IF(R10="1세대1주택",R12,60%) -> 0.6 | W12: =IF(W10="1세대1주택", IF(W11<=3*10^8,43%, IF(W11<=6*10^8,44%, 45%)), VLOOKUP(W10,t!$H$3:$I$9,2,0)) -> 0.7 | Y12: 공정시장가액비율 | Z12: =IF(Z$10="1세대1주택", IF(Z11<=3*10^8,43%, IF(Z11<=6*10^8,44%, 45%)), VLOOKUP(Z$10,t!$H$3:$I$9,2,0)) -> 0.6 | AA12: =IF(AA$10="1세대1주택", IF(AA11<=3*10^8,43%, IF(AA11<=6*10^8,44%, 45%)), VLOOKUP(AA$10,t!$H$3:$I$9,2,0)) -> 0.6 | AB12: =IF(AB$10="1세대1주택", IF(AB11<=3*10^8,43%, IF(AB11<=6*10^8,44%, 45%)), VLOOKUP(AB$10,t!$H$3:$I$9,2,0)) -> 0.6 | AC12: =IF(AC$10="1세대1주택", IF(AC11<=3*10^8,43%, IF(AC11<=6*10^8,44%, 45%)), VLOOKUP(AC$10,t!$H$3:$I$9,2,0)) -> 0.6 | AD12: =IF(Z10="1세대1주택",Z12,60%) -> 0.6 | AE12: =IF(AE10="1세대1주택", IF(AE11<=3*10^8,43%, IF(AE11<=6*10^8,44%, 45%)), VLOOKUP(AE10,t!$H$3:$I$9,2,0)) -> 0.7 | AG12: 공정시장가액비율 | AH12: =IF(AH$10="1세대1주택", IF(AH11<=3*10^8,43%, IF(AH11<=6*10^8,44%, 45%)), VLOOKUP(AH$10,t!$H$3:$I$9,2,0)) -> 0.6 | AI12: =IF(AI$10="1세대1주택", IF(AI11<=3*10^8,43%, IF(AI11<=6*10^8,44%, 45%)), VLOOKUP(AI$10,t!$H$3:$I$9,2,0)) -> 0.6 | AJ12: =IF(AJ$10="1세대1주택", IF(AJ11<=3*10^8,43%, IF(AJ11<=6*10^8,44%, 45%)), VLOOKUP(AJ$10,t!$H$3:$I$9,2,0)) -> 0.6 | AK12: =IF(AK$10="1세대1주택", IF(AK11<=3*10^8,43%, IF(AK11<=6*10^8,44%, 45%)), VLOOKUP(AK$10,t!$H$3:$I$9,2,0)) -> 0.6 | AL12: =IF(AH10="1세대1주택",AH12,60%) -> 0.6 | AM12: =IF(AM10="1세대1주택", IF(AM11<=3*10^8,43%, IF(AM11<=6*10^8,44%, 45%)), VLOOKUP(AM10,t!$H$3:$I$9,2,0)) -> 0.7
A13: 과세표준(주택상한) | B13: =IF(RIGHT(B10,2)="주택",MIN(B11*B12,B23*B12+B11*B12*5%),B11*B12) -> 2100000000 | C13: =IF(RIGHT(C10,2)="주택",MIN(C11*C12,C23*C12+C11*C12*5%),C11*C12) -> 514500000 | D13: =IF(RIGHT(D10,2)="주택",MIN(D11*D12,D23*D12+D11*D12*5%),D11*D12) -> 771750000 | E13: =IF(RIGHT(E10,2)="주택",MIN(E11*E12,E23*E12+E11*E12*5%),E11*E12) -> 1089000000 | F13: =F11*F12 -> 5205000000 | G13: =IF(RIGHT(G10,2)="주택",MIN(G11*G12,G24*G12+G11*G12*5%),G11*G12) -> 0 | I13: 재산세 과세표준 | J13: =IF(RIGHT(J10,2)="주택",MIN(J11*J12,J23*J12+J11*J12*5%),J11*J12) -> 2220750000 | K13: =IF(RIGHT(K10,2)="주택",MIN(K11*K12,K23*K12+K11*K12*5%),K11*K12) -> 729675000 | L13: =IF(RIGHT(L10,2)="주택",MIN(L11*L12,L23*L12+L11*L12*5%),L11*L12) -> 1.0945125e+09 | M13: =IF(RIGHT(M10,2)="주택",MIN(M11*M12,M23*M12+M11*M12*5%),M11*M12) -> 1459350000 | N13: =N11*N12 -> 5985750000 | O13: =IF(RIGHT(O10,2)="주택",MIN(O11*O12,O23*O12+O11*O12*5%),O11*O12) -> 0 | Q13: 재산세 과세표준 | R13: =IF(RIGHT(R10,2)="주택",MIN(R11*R12,R23*R12+R11*R12*5%),R11*R12) -> 2.415e+09 | S13: =IF(RIGHT(S10,2)="주택",MIN(S11*S12,S23*S12+S11*S12*5%),S11*S12) -> 793500000 | T13: =IF(RIGHT(T10,2)="주택",MIN(T11*T12,T23*T12+T11*T12*5%),T11*T12) -> 1.19025e+09 | U13: =IF(RIGHT(U10,2)="주택",MIN(U11*U12,U23*U12+U11*U12*5%),U11*U12) -> 1587000000 | V13: =V11*V12 -> 5985750000 | W13: =IF(RIGHT(W10,2)="주택",MIN(W11*W12,W23*W12+W11*W12*5%),W11*W12) -> 0 | Y13: 재산세 과세표준 | Z13: =IF(RIGHT(Z10,2)="주택",MIN(Z11*Z12,Z23*Z12+Z11*Z12*5%),Z11*Z12) -> 2.5538625e+09 | AA13: =IF(RIGHT(AA10,2)="주택",MIN(AA11*AA12,AA23*AA12+AA11*AA12*5%),AA11*AA12) -> 839126250 | AB13: =IF(RIGHT(AB10,2)="주택",MIN(AB11*AB12,AB23*AB12+AB11*AB12*5%),AB11*AB12) -> 1.2586894e+09 | AC13: =IF(RIGHT(AC10,2)="주택",MIN(AC11*AC12,AC23*AC12+AC11*AC12*5%),AC11*AC12) -> 1678252500 | AD13: =AD11*AD12 -> 6.8836125e+09 | AE13: =IF(RIGHT(AE10,2)="주택",MIN(AE11*AE12,AE23*AE12+AE11*AE12*5%),AE11*AE12) -> 0 | AG13: 재산세 과세표준 | AH13: =IF(RIGHT(AH10,2)="주택",MIN(AH11*AH12,AH23*AH12+AH11*AH12*5%),AH11*AH12) -> 2.9299987e+09 | AI13: =IF(RIGHT(AI10,2)="주택",MIN(AI11*AI12,AI23*AI12+AI11*AI12*5%),AI11*AI12) -> 921650250 | AJ13: =IF(RIGHT(AJ10,2)="주택",MIN(AJ11*AJ12,AJ23*AJ12+AJ11*AJ12*5%),AJ11*AJ12) -> 1.4098511e+09 | AK13: =IF(RIGHT(AK10,2)="주택",MIN(AK11*AK12,AK23*AK12+AK11*AK12*5%),AK11*AK12) -> 1916302500 | AL13: =AL11*AL12 -> 7.3027789e+09 | AM13: =IF(RIGHT(AM10,2)="주택",MIN(AM11*AM12,AM23*AM12+AM11*AM12*5%),AM11*AM12) -> 0
A14: t | B14: {=IF(AND(B10="1세대1주택",B11<=9*10^8),INDEX(t!$D$3:$D$6,MATCH(TRUE,B13<=t!$A$3:$A$6,0)),INDEX(t!$B$3:$B$6,MATCH(TRUE,B13<=t!$A$3:$A$6,0)))} -> 0.004 | C14: {=IF(AND(C10="1세대1주택",C11<=9*10^8),INDEX(t!$D$3:$D$6,MATCH(TRUE,C13<=t!$A$3:$A$6,0)),INDEX(t!$B$3:$B$6,MATCH(TRUE,C13<=t!$A$3:$A$6,0)))} -> 0.004 | D14: {=IF(AND(D10="1세대1주택",D11<=9*10^8),INDEX(t!$D$3:$D$6,MATCH(TRUE,D13<=t!$A$3:$A$6,0)),INDEX(t!$B$3:$B$6,MATCH(TRUE,D13<=t!$A$3:$A$6,0)))} -> 0.004 | E14: {=IF(AND(E10="1세대1주택",E11<=9*10^8),INDEX(t!$D$3:$D$6,MATCH(TRUE,E13<=t!$A$3:$A$6,0)),INDEX(t!$B$3:$B$6,MATCH(TRUE,E13<=t!$A$3:$A$6,0)))} -> 0.004 | F14: {=INDEX(t!$B$3:$B$6,MATCH(TRUE,F13<=t!$A$3:$A$6,0))} -> 0.004 | G14: 0.0025 | I14: t | J14: {=IF(AND(J10="1세대1주택",J11<=9*10^8),INDEX(t!$D$3:$D$6,MATCH(TRUE,J13<=t!$A$3:$A$6,0)),INDEX(t!$B$3:$B$6,MATCH(TRUE,J13<=t!$A$3:$A$6,0)))} -> 0.004 | K14: {=IF(AND(K10="1세대1주택",K11<=9*10^8),INDEX(t!$D$3:$D$6,MATCH(TRUE,K13<=t!$A$3:$A$6,0)),INDEX(t!$B$3:$B$6,MATCH(TRUE,K13<=t!$A$3:$A$6,0)))} -> 0.004 | L14: {=IF(AND(L10="1세대1주택",L11<=9*10^8),INDEX(t!$D$3:$D$6,MATCH(TRUE,L13<=t!$A$3:$A$6,0)),INDEX(t!$B$3:$B$6,MATCH(TRUE,L13<=t!$A$3:$A$6,0)))} -> 0.004 | M14: {=IF(AND(M10="1세대1주택",M11<=9*10^8),INDEX(t!$D$3:$D$6,MATCH(TRUE,M13<=t!$A$3:$A$6,0)),INDEX(t!$B$3:$B$6,MATCH(TRUE,M13<=t!$A$3:$A$6,0)))} -> 0.004 | N14: {=INDEX(t!$B$3:$B$6,MATCH(TRUE,N13<=t!$A$3:$A$6,0))} -> 0.004 | O14: 0.0025 | Q14: t | R14: {=IF(AND(R10="1세대1주택",R11<=9*10^8),INDEX(t!$D$3:$D$6,MATCH(TRUE,R13<=t!$A$3:$A$6,0)),INDEX(t!$B$3:$B$6,MATCH(TRUE,R13<=t!$A$3:$A$6,0)))} -> 0.004 | S14: {=IF(AND(S10="1세대1주택",S11<=9*10^8),INDEX(t!$D$3:$D$6,MATCH(TRUE,S13<=t!$A$3:$A$6,0)),INDEX(t!$B$3:$B$6,MATCH(TRUE,S13<=t!$A$3:$A$6,0)))} -> 0.004 | T14: {=IF(AND(T10="1세대1주택",T11<=9*10^8),INDEX(t!$D$3:$D$6,MATCH(TRUE,T13<=t!$A$3:$A$6,0)),INDEX(t!$B$3:$B$6,MATCH(TRUE,T13<=t!$A$3:$A$6,0)))} -> 0.004 | U14: {=IF(AND(U10="1세대1주택",U11<=9*10^8),INDEX(t!$D$3:$D$6,MATCH(TRUE,U13<=t!$A$3:$A$6,0)),INDEX(t!$B$3:$B$6,MATCH(TRUE,U13<=t!$A$3:$A$6,0)))} -> 0.004 | V14: {=INDEX(t!$B$3:$B$6,MATCH(TRUE,V13<=t!$A$3:$A$6,0))} -> 0.004 | W14: 0.0025 | Y14: t | Z14: {=IF(AND(Z10="1세대1주택",Z11<=9*10^8),INDEX(t!$D$3:$D$6,MATCH(TRUE,Z13<=t!$A$3:$A$6,0)),INDEX(t!$B$3:$B$6,MATCH(TRUE,Z13<=t!$A$3:$A$6,0)))} -> 0.004 | AA14: {=IF(AND(AA10="1세대1주택",AA11<=9*10^8),INDEX(t!$D$3:$D$6,MATCH(TRUE,AA13<=t!$A$3:$A$6,0)),INDEX(t!$B$3:$B$6,MATCH(TRUE,AA13<=t!$A$3:$A$6,0)))} -> 0.004 | AB14: {=IF(AND(AB10="1세대1주택",AB11<=9*10^8),INDEX(t!$D$3:$D$6,MATCH(TRUE,AB13<=t!$A$3:$A$6,0)),INDEX(t!$B$3:$B$6,MATCH(TRUE,AB13<=t!$A$3:$A$6,0)))} -> 0.004 | AC14: {=IF(AND(AC10="1세대1주택",AC11<=9*10^8),INDEX(t!$D$3:$D$6,MATCH(TRUE,AC13<=t!$A$3:$A$6,0)),INDEX(t!$B$3:$B$6,MATCH(TRUE,AC13<=t!$A$3:$A$6,0)))} -> 0.004 | AD14: {=INDEX(t!$B$3:$B$6,MATCH(TRUE,AD13<=t!$A$3:$A$6,0))} -> 0.004 | AE14: 0.0025 | AG14: t | AH14: {=IF(AND(AH10="1세대1주택",AH11<=9*10^8),INDEX(t!$D$3:$D$6,MATCH(TRUE,AH13<=t!$A$3:$A$6,0)),INDEX(t!$B$3:$B$6,MATCH(TRUE,AH13<=t!$A$3:$A$6,0)))} -> 0.004 | AI14: {=IF(AND(AI10="1세대1주택",AI11<=9*10^8),INDEX(t!$D$3:$D$6,MATCH(TRUE,AI13<=t!$A$3:$A$6,0)),INDEX(t!$B$3:$B$6,MATCH(TRUE,AI13<=t!$A$3:$A$6,0)))} -> 0.004 | AJ14: {=IF(AND(AJ10="1세대1주택",AJ11<=9*10^8),INDEX(t!$D$3:$D$6,MATCH(TRUE,AJ13<=t!$A$3:$A$6,0)),INDEX(t!$B$3:$B$6,MATCH(TRUE,AJ13<=t!$A$3:$A$6,0)))} -> 0.004 | AK14: {=IF(AND(AK10="1세대1주택",AK11<=9*10^8),INDEX(t!$D$3:$D$6,MATCH(TRUE,AK13<=t!$A$3:$A$6,0)),INDEX(t!$B$3:$B$6,MATCH(TRUE,AK13<=t!$A$3:$A$6,0)))} -> 0.004 | AL14: {=INDEX(t!$B$3:$B$6,MATCH(TRUE,AL13<=t!$A$3:$A$6,0))} -> 0.004 | AM14: 0.0025
A15: 산출세액 | B15: =B13*B14-VLOOKUP(B14,IF(AND(B10="1세대1주택",B11<=9*10^8),t!$D$2:$E$6,t!$B$2:$C$6),2,0) -> 7770000 | C15: =C13*C14-VLOOKUP(C14,IF(AND(C10="1세대1주택",C11<=9*10^8),t!$D$2:$E$6,t!$B$2:$C$6),2,0) -> 1428000 | D15: =D13*D14-VLOOKUP(D14,IF(AND(D10="1세대1주택",D11<=9*10^8),t!$D$2:$E$6,t!$B$2:$C$6),2,0) -> 2457000 | E15: =E13*E14-VLOOKUP(E14,IF(AND(E10="1세대1주택",E11<=9*10^8),t!$D$2:$E$6,t!$B$2:$C$6),2,0) -> 3726000 | F15: =F13*F14-VLOOKUP(F14,t!$B$2:$C$6,2,0) -> 20190000 | G15: =G13*0.25% -> 0 | I15: 산출세액 | J15: =J13*J14-VLOOKUP(J14,IF(AND(J10="1세대1주택",J11<=9*10^8),t!$D$2:$E$6,t!$B$2:$C$6),2,0) -> 8253000 | K15: =K13*K14-VLOOKUP(K14,IF(AND(K10="1세대1주택",K11<=9*10^8),t!$D$2:$E$6,t!$B$2:$C$6),2,0) -> 2288700 | L15: =L13*L14-VLOOKUP(L14,IF(AND(L10="1세대1주택",L11<=9*10^8),t!$D$2:$E$6,t!$B$2:$C$6),2,0) -> 3748050 | M15: =M13*M14-VLOOKUP(M14,IF(AND(M10="1세대1주택",M11<=9*10^8),t!$D$2:$E$6,t!$B$2:$C$6),2,0) -> 5207400 | N15: =N13*N14-VLOOKUP(N14,t!$B$2:$C$6,2,0) -> 23313000 | O15: =O13*0.25% -> 0 | Q15: 산출세액 | R15: =R13*R14-VLOOKUP(R14,IF(AND(R10="1세대1주택",R11<=9*10^8),t!$D$2:$E$6,t!$B$2:$C$6),2,0) -> 9030000 | S15: =S13*S14-VLOOKUP(S14,IF(AND(S10="1세대1주택",S11<=9*10^8),t!$D$2:$E$6,t!$B$2:$C$6),2,0) -> 2544000 | T15: =T13*T14-VLOOKUP(T14,IF(AND(T10="1세대1주택",T11<=9*10^8),t!$D$2:$E$6,t!$B$2:$C$6),2,0) -> 4131000 | U15: =U13*U14-VLOOKUP(U14,IF(AND(U10="1세대1주택",U11<=9*10^8),t!$D$2:$E$6,t!$B$2:$C$6),2,0) -> 5718000 | V15: =V13*V14-VLOOKUP(V14,t!$B$2:$C$6,2,0) -> 23313000 | W15: =W13*0.25% -> 0 | Y15: 산출세액 | Z15: =Z13*Z14-VLOOKUP(Z14,IF(AND(Z10="1세대1주택",Z11<=9*10^8),t!$D$2:$E$6,t!$B$2:$C$6),2,0) -> 9585450 | AA15: =AA13*AA14-VLOOKUP(AA14,IF(AND(AA10="1세대1주택",AA11<=9*10^8),t!$D$2:$E$6,t!$B$2:$C$6),2,0) -> 2726505 | AB15: =AB13*AB14-VLOOKUP(AB14,IF(AND(AB10="1세대1주택",AB11<=9*10^8),t!$D$2:$E$6,t!$B$2:$C$6),2,0) -> 4404757.5 | AC15: =AC13*AC14-VLOOKUP(AC14,IF(AND(AC10="1세대1주택",AC11<=9*10^8),t!$D$2:$E$6,t!$B$2:$C$6),2,0) -> 6083010 | AD15: =AD13*AD14-VLOOKUP(AD14,t!$B$2:$C$6,2,0) -> 26904450 | AE15: =AE13*0.25% -> 0 | AG15: 산출세액 | AH15: =AH13*AH14-VLOOKUP(AH14,IF(AND(AH10="1세대1주택",AH11<=9*10^8),t!$D$2:$E$6,t!$B$2:$C$6),2,0) -> 11089995 | AI15: =AI13*AI14-VLOOKUP(AI14,IF(AND(AI10="1세대1주택",AI11<=9*10^8),t!$D$2:$E$6,t!$B$2:$C$6),2,0) -> 3056601 | AJ15: =AJ13*AJ14-VLOOKUP(AJ14,IF(AND(AJ10="1세대1주택",AJ11<=9*10^8),t!$D$2:$E$6,t!$B$2:$C$6),2,0) -> 5009404.5 | AK15: =AK13*AK14-VLOOKUP(AK14,IF(AND(AK10="1세대1주택",AK11<=9*10^8),t!$D$2:$E$6,t!$B$2:$C$6),2,0) -> 7035210 | AL15: =AL13*AL14-VLOOKUP(AL14,t!$B$2:$C$6,2,0) -> 28581115 | AM15: =AM13*0.25% -> 0
A16: 재산세액 | B16: =B15 -> 7770000 | C16: =C15 -> 1428000 | D16: =D15 -> 2457000 | E16: =E15 -> 3726000 | F16: =SUM(B16:E16) -> 15381000 | G16: =MIN(G15,F27*150%) -> 0 | I16: 재산세액 | J16: =J15 -> 8253000 | K16: =K15 -> 2288700 | L16: =L15 -> 3748050 | M16: =M15 -> 5207400 | N16: =SUM(J16:M16) -> 19497150 | O16: =MIN(O15,O27*150%) -> -465660 | Q16: 재산세액 | R16: =R15 -> 9030000 | S16: =S15 -> 2544000 | T16: =T15 -> 4131000 | U16: =U15 -> 5718000 | V16: =SUM(R16:U16) -> 21423000 | W16: =MIN(W15,W27*150%) -> 0 | Y16: 재산세액 | Z16: =Z15 -> 9585450 | AA16: =AA15 -> 2726505 | AB16: =AB15 -> 4404757.5 | AC16: =AC15 -> 6083010 | AD16: =SUM(Z16:AC16) -> 22799722 | AE16: =MIN(AE15,AE27*150%) -> 0 | AG16: 재산세액 | AH16: =AH15 -> 11089995 | AI16: =AI15 -> 3056601 | AJ16: =AJ15 -> 5009404.5 | AK16: =AK15 -> 7035210 | AL16: =SUM(AH16:AK16) -> 26191210 | AM16: =MIN(AM15,AM27*150%) -> 0
A17: 도시지역분 | B17: =B$13*0.14% -> 2940000 | C17: =C$13*0.14% -> 720300 | D17: =D$13*0.14% -> 1080450 | E17: =E$13*0.14% -> 1524600 | G17: =G$13*0.14% -> 0 | I17: 도시지역분 | J17: =J$13*0.14% -> 3109050 | K17: =K$13*0.14% -> 1021545 | L17: =L$13*0.14% -> 1532317.5 | M17: =M$13*0.14% -> 2043090 | O17: =O$13*0.14% -> 0 | Q17: 도시지역분 | R17: =R$13*0.14% -> 3381000 | S17: =S$13*0.14% -> 1110900 | T17: =T$13*0.14% -> 1666350 | U17: =U$13*0.14% -> 2221800 | W17: =W$13*0.14% -> 0 | Y17: 도시지역분 | Z17: =Z$13*0.14% -> 3575407.5 | AA17: =AA$13*0.14% -> 1174776.8 | AB17: =AB$13*0.14% -> 1762165.1 | AC17: =AC$13*0.14% -> 2349553.5 | AE17: =AE$13*0.14% -> 0 | AG17: 도시지역분 | AH17: =AH$13*0.14% -> 4101998.2 | AI17: =AI$13*0.14% -> 1290310.4 | AJ17: =AJ$13*0.14% -> 1973791.6 | AK17: =AK$13*0.14% -> 2682823.5 | AM17: =AM$13*0.14% -> 0
A18: 지역자원시설세 | G18: =IF(G13<=6000000, G13*0.04%, IF(G13<=13000000, 2400+(G13-6000000)*0.05%, IF(G13<=26000000, 5900+(G13-13000000)*0.06%, IF(G13<=39000000, 13700+(G13-26000000)*0.08%, IF(G13<=64000000, 24100+(G13-39000000)*0.1%, 49100+(G13-64000000)*0.12% ) ) ) ) ) -> 0 | I18: 지역자원시설세 | O18: =IF(O13<=6000000, O13*0.04%, IF(O13<=13000000, 2400+(O13-6000000)*0.05%, IF(O13<=26000000, 5900+(O13-13000000)*0.06%, IF(O13<=39000000, 13700+(O13-26000000)*0.08%, IF(O13<=64000000, 24100+(O13-39000000)*0.1%, 49100+(O13-64000000)*0.12% ) ) ) ) ) -> 0 | Q18: 지역자원시설세 | W18: =IF(W13<=6000000, W13*0.04%, IF(W13<=13000000, 2400+(W13-6000000)*0.05%, IF(W13<=26000000, 5900+(W13-13000000)*0.06%, IF(W13<=39000000, 13700+(W13-26000000)*0.08%, IF(W13<=64000000, 24100+(W13-39000000)*0.1%, 49100+(W13-64000000)*0.12% ) ) ) ) ) -> 0 | Y18: 지역자원시설세 | AE18: =IF(AE13<=6000000, AE13*0.04%, IF(AE13<=13000000, 2400+(AE13-6000000)*0.05%, IF(AE13<=26000000, 5900+(AE13-13000000)*0.06%, IF(AE13<=39000000, 13700+(AE13-26000000)*0.08%, IF(AE13<=64000000, 24100+(AE13-39000000)*0.1%, 49100+(AE13-64000000)*0.12% ) ) ) ) ) -> 0 | AG18: 지역자원시설세 | AM18: =IF(AM13<=6000000, AM13*0.04%, IF(AM13<=13000000, 2400+(AM13-6000000)*0.05%, IF(AM13<=26000000, 5900+(AM13-13000000)*0.06%, IF(AM13<=39000000, 13700+(AM13-26000000)*0.08%, IF(AM13<=64000000, 24100+(AM13-39000000)*0.1%, 49100+(AM13-64000000)*0.12% ) ) ) ) ) -> 0
A19: 지방교육세 | B19: =B$16*0.2 -> 1554000 | C19: =C$16*0.2 -> 285600 | D19: =D$16*0.2 -> 491400 | E19: =E$16*0.2 -> 745200 | G19: =G$16*0.2 -> 0 | I19: 지방교육세 | J19: =J$16*0.2 -> 1650600 | K19: =K$16*0.2 -> 457740 | L19: =L$16*0.2 -> 749610 | M19: =M$16*0.2 -> 1041480 | O19: =O$16*0.2 -> -93132 | Q19: 지방교육세 | R19: =R$16*0.2 -> 1806000 | S19: =S$16*0.2 -> 508800 | T19: =T$16*0.2 -> 826200 | U19: =U$16*0.2 -> 1143600 | W19: =W$16*0.2 -> 0 | Y19: 지방교육세 | Z19: =Z$16*0.2 -> 1917090 | AA19: =AA$16*0.2 -> 545301 | AB19: =AB$16*0.2 -> 880951.5 | AC19: =AC$16*0.2 -> 1216602 | AE19: =AE$16*0.2 -> 0 | AG19: 지방교육세 | AH19: =AH$16*0.2 -> 2217999 | AI19: =AI$16*0.2 -> 611320.2 | AJ19: =AJ$16*0.2 -> 1001880.9 | AK19: =AK$16*0.2 -> 1407042 | AM19: =AM$16*0.2 -> 0
A20: 재산세납부액 | B20: =SUM(B16:B19) -> 12264000 | C20: =SUM(C16:C19) -> 2433900 | D20: =SUM(D16:D19) -> 4028850 | E20: =SUM(E16:E19) -> 5995800 | G20: =SUM(G16:G19) -> 0 | I20: 재산세납부액 | J20: =SUM(J16:J19) -> 13012650 | K20: =SUM(K16:K19) -> 3767985 | L20: =SUM(L16:L19) -> 6029977.5 | M20: =SUM(M16:M19) -> 8291970 | O20: =SUM(O16:O19) -> -558792 | Q20: 재산세납부액 | R20: =SUM(R16:R19) -> 14217000 | S20: =SUM(S16:S19) -> 4163700 | T20: =SUM(T16:T19) -> 6623550 | U20: =SUM(U16:U19) -> 9083400 | W20: =SUM(W16:W19) -> 0 | Y20: 재산세납부액 | Z20: =SUM(Z16:Z19) -> 15077947 | AA20: =SUM(AA16:AA19) -> 4446582.8 | AB20: =SUM(AB16:AB19) -> 7047874.1 | AC20: =SUM(AC16:AC19) -> 9649165.5 | AE20: =SUM(AE16:AE19) -> 0 | AG20: 재산세납부액 | AH20: =SUM(AH16:AH19) -> 17409992 | AI20: =SUM(AI16:AI19) -> 4958231.5 | AJ20: =SUM(AJ16:AJ19) -> 7985077 | AK20: =SUM(AK16:AK19) -> 11125076 | AM20: =SUM(AM16:AM19) -> 0
F22: 전년도 | G22: 전년도 | N22: 전년도 | O22: 전년도 | V22: 전년도 | W22: 전년도 | AD22: 전년도 | AE22: 전년도 | AL22: 전년도 | AM22: 전년도
A23: 시가표준 | B23: 4890000000 | C23: 800000000 | D23: 1200000000 | E23: 1700000000 | I23: 시가표준 | J23: =B11 -> 3500000000 | K23: =C11 -> 1150000000 | L23: =D11 -> 1.725e+09 | M23: =E11 -> 2300000000 | Q23: 시가표준 | R23: =J11 -> 4.025e+09 | S23: =K11 -> 1322500000 | T23: =L11 -> 1.98375e+09 | U23: =M11 -> 2645000000 | Y23: 시가표준 | Z23: =R11 -> 4.025e+09 | AA23: =S11 -> 1322500000 | AB23: =T11 -> 1.98375e+09 | AC23: =U11 -> 2645000000 | AG23: 시가표준 | AH23: =Z11 -> 4.62875e+09 | AI23: =AA11 -> 1520875000 | AJ23: =AB11 -> 2.2813125e+09 | AK23: =AC11 -> 3041750000
A24: 과세표준 | B24: =B23*IF(B10="1세대1주택",B12,60%) -> 2934000000 | C24: =C23*IF(C10="1세대1주택",C12,60%) -> 480000000 | D24: =D23*IF(D10="1세대1주택",D12,60%) -> 720000000 | E24: =E23*IF(E10="1세대1주택",E12,60%) -> 1020000000 | I24: 과세표준 | J24: =J23*0.6 -> 2100000000 | K24: =K23*0.6 -> 690000000 | L24: =L23*0.6 -> 1.035e+09 | M24: =M23*0.6 -> 1380000000 | Q24: 과세표준 | R24: =R23*0.6 -> 2.415e+09 | S24: =S23*0.6 -> 793500000 | T24: =T23*0.6 -> 1.19025e+09 | U24: =U23*0.6 -> 1587000000 | Y24: 과세표준 | Z24: =Z23*0.6 -> 2.415e+09 | AA24: =AA23*0.6 -> 793500000 | AB24: =AB23*0.6 -> 1.19025e+09 | AC24: =AC23*0.6 -> 1587000000 | AG24: 과세표준 | AH24: =AH23*0.6 -> 2.77725e+09 | AI24: =AI23*0.6 -> 912525000 | AJ24: =AJ23*0.6 -> 1.3687875e+09 | AK24: =AK23*0.6 -> 1825050000
A25: t | B25: {=INDEX(t!$B$3:$B$6,MATCH(TRUE,B13<=t!$A$3:$A$6,0))} -> 0.004 | C25: {=INDEX(t!$B$3:$B$6,MATCH(TRUE,C13<=t!$A$3:$A$6,0))} -> 0.004 | D25: {=INDEX(t!$B$3:$B$6,MATCH(TRUE,D13<=t!$A$3:$A$6,0))} -> 0.004 | E25: {=INDEX(t!$B$3:$B$6,MATCH(TRUE,E13<=t!$A$3:$A$6,0))} -> 0.004 | I25: t | J25: {=INDEX(t!$B$3:$B$6,MATCH(TRUE,J13<=t!$A$3:$A$6,0))} -> 0.004 | K25: {=INDEX(t!$B$3:$B$6,MATCH(TRUE,K13<=t!$A$3:$A$6,0))} -> 0.004 | L25: {=INDEX(t!$B$3:$B$6,MATCH(TRUE,L13<=t!$A$3:$A$6,0))} -> 0.004 | M25: {=INDEX(t!$B$3:$B$6,MATCH(TRUE,M13<=t!$A$3:$A$6,0))} -> 0.004 | Q25: t | R25: {=INDEX(t!$B$3:$B$6,MATCH(TRUE,R13<=t!$A$3:$A$6,0))} -> 0.004 | S25: {=INDEX(t!$B$3:$B$6,MATCH(TRUE,S13<=t!$A$3:$A$6,0))} -> 0.004 | T25: {=INDEX(t!$B$3:$B$6,MATCH(TRUE,T13<=t!$A$3:$A$6,0))} -> 0.004 | U25: {=INDEX(t!$B$3:$B$6,MATCH(TRUE,U13<=t!$A$3:$A$6,0))} -> 0.004 | Y25: t | Z25: {=INDEX(t!$B$3:$B$6,MATCH(TRUE,Z13<=t!$A$3:$A$6,0))} -> 0.004 | AA25: {=INDEX(t!$B$3:$B$6,MATCH(TRUE,AA13<=t!$A$3:$A$6,0))} -> 0.004 | AB25: {=INDEX(t!$B$3:$B$6,MATCH(TRUE,AB13<=t!$A$3:$A$6,0))} -> 0.004 | AC25: {=INDEX(t!$B$3:$B$6,MATCH(TRUE,AC13<=t!$A$3:$A$6,0))} -> 0.004 | AG25: t | AH25: {=INDEX(t!$B$3:$B$6,MATCH(TRUE,AH13<=t!$A$3:$A$6,0))} -> 0.004 | AI25: {=INDEX(t!$B$3:$B$6,MATCH(TRUE,AI13<=t!$A$3:$A$6,0))} -> 0.004 | AJ25: {=INDEX(t!$B$3:$B$6,MATCH(TRUE,AJ13<=t!$A$3:$A$6,0))} -> 0.004 | AK25: {=INDEX(t!$B$3:$B$6,MATCH(TRUE,AK13<=t!$A$3:$A$6,0))} -> 0.004
A26: 전연도 재산세상당액 | B26: =B24*B25-VLOOKUP(B25,t!$B$2:$C$6,2,0) -> 11106000 | C26: =C24*C25-VLOOKUP(C25,t!$B$2:$C$6,2,0) -> 1290000 | D26: =D24*D25-VLOOKUP(D25,t!$B$2:$C$6,2,0) -> 2250000 | E26: =E24*E25-VLOOKUP(E25,t!$B$2:$C$6,2,0) -> 3450000 | F26: =SUMPRODUCT(B26:E26,B35:E35) -> 17451000 | G26: =SUMPRODUCT(B26:E26,B68:E68) -> 645000 | I26: 전연도 재산세상당액 | J26: =J24*J25-VLOOKUP(J25,t!$B$2:$C$6,2,0) -> 7770000 | K26: =K24*K25-VLOOKUP(K25,t!$B$2:$C$6,2,0) -> 2130000 | L26: =L24*L25-VLOOKUP(L25,t!$B$2:$C$6,2,0) -> 3510000 | M26: =M24*M25-VLOOKUP(M25,t!$B$2:$C$6,2,0) -> 4890000 | N26: =SUMPRODUCT(J26:M26,J35:M35) -> 17235000 | O26: =SUMPRODUCT(J26:M26,J68:M68) -> 1065000 | Q26: 전연도 재산세상당액 | R26: =R24*R25-VLOOKUP(R25,t!$B$2:$C$6,2,0) -> 9030000 | S26: =S24*S25-VLOOKUP(S25,t!$B$2:$C$6,2,0) -> 2544000 | T26: =T24*T25-VLOOKUP(T25,t!$B$2:$C$6,2,0) -> 4131000 | U26: =U24*U25-VLOOKUP(U25,t!$B$2:$C$6,2,0) -> 5718000 | V26: =SUMPRODUCT(R26:U26,R35:U35) -> 20151000 | W26: =SUMPRODUCT(R26:U26,R68:U68) -> 1272000 | Y26: 전연도 재산세상당액 | Z26: =Z24*Z25-VLOOKUP(Z25,t!$B$2:$C$6,2,0) -> 9030000 | AA26: =AA24*AA25-VLOOKUP(AA25,t!$B$2:$C$6,2,0) -> 2544000 | AB26: =AB24*AB25-VLOOKUP(AB25,t!$B$2:$C$6,2,0) -> 4131000 | AC26: =AC24*AC25-VLOOKUP(AC25,t!$B$2:$C$6,2,0) -> 5718000 | AD26: =SUMPRODUCT(Z26:AC26,Z35:AC35) -> 20151000 | AE26: =SUMPRODUCT(Z26:AC26,Z68:AC68) -> 1272000 | AG26: 전연도 재산세상당액 | AH26: =AH24*AH25-VLOOKUP(AH25,t!$B$2:$C$6,2,0) -> 10479000 | AI26: =AI24*AI25-VLOOKUP(AI25,t!$B$2:$C$6,2,0) -> 3020100 | AJ26: =AJ24*AJ25-VLOOKUP(AJ25,t!$B$2:$C$6,2,0) -> 4845150 | AK26: =AK24*AK25-VLOOKUP(AK25,t!$B$2:$C$6,2,0) -> 6670200 | AL26: =SUMPRODUCT(AH26:AK26,AH35:AK35) -> 23504400 | AM26: =SUMPRODUCT(AH26:AK26,AH68:AK68) -> 1510050
A27: 전년도 종부세상당액 | F27: =F57 -> 82191407 | G27: =F88 -> -92727.273 | I27: 전년도 종부세상당액 | N27: =N57 -> 80700134 | O27: =N88 -> -310440 | Q27: 전년도 종부세상당액 | V27: =V57 -> 1.4241582e+08 | W27: =V88 -> 331009.48 | Y27: 전년도 종부세상당액 | AD27: =AD57 -> 1.7527522e+08 | AE27: =AD88 -> 378296.55 | AG27: 전년도 종부세상당액 | AL27: =AL57 -> 2.1731108e+08 | AM27: =AL90 -> 567297.05
A28: 세부담상한액 | F28: =SUM(F26,F27)*150% -> 1.4946361e+08 | G28: =SUM(G26,G27)*150% -> 828409.09 | I28: 세부담상한액 | N28: =SUM(N26,N27)*200% -> 1.9587027e+08 | O28: =SUM(O26,O27)*200% -> 1509120 | Q28: 세부담상한액 | V28: =SUM(V26,V27)*200% -> 3.2513364e+08 | W28: =SUM(W26,W27)*200% -> 3206019 | Y28: 세부담상한액 | AD28: =SUM(AD26,AD27)*200% -> 3.9085245e+08 | AE28: =SUM(AE26,AE27)*200% -> 3300593.1 | AG28: 세부담상한액 | AL28: =SUM(AL26,AL27)*200% -> 4.8163097e+08 | AM28: =SUM(AM26,AM27)*200% -> 4154694.1
B32: =A9 -> 2026 | F32: 전년도 | J32: =B32+1 -> 2027 | N32: 전년도 | R32: =J32+1 -> 2028 | V32: 전년도 | Z32: =R32+1 -> 2029 | AD32: 전년도 | AH32: =Z32+1 -> 2030 | AL32: 전년도
B33: =IF(OR($B$5="1세대1주택"),"1세대1주택","주택") -> 주택 | C33: =IF(OR($B$5="1세대1주택"),"1세대1주택","주택") -> 주택 | D33: =IF(OR($B$5="1세대1주택"),"1세대1주택","주택") -> 주택 | E33: =IF(OR($B$5="1세대1주택"),"1세대1주택","주택") -> 주택 | F33: =IF(OR($B$5="1세대1주택"),"1세대1주택","주택") -> 주택 | J33: =J10 -> 주택 | K33: =K10 -> 주택 | L33: =L10 -> 주택 | M33: =M10 -> 주택 | N33: =IF(OR($B$5="1세대1주택"),"1세대1주택","주택") -> 주택 | R33: =R10 -> 주택 | S33: =S10 -> 주택 | T33: =T10 -> 주택 | U33: =U10 -> 주택 | V33: =IF(OR($B$5="1세대1주택"),"1세대1주택","주택") -> 주택 | Z33: =Z10 -> 주택 | AA33: =AA10 -> 주택 | AB33: =AB10 -> 주택 | AC33: =AC10 -> 주택 | AD33: =IF(OR($B$5="1세대1주택"),"1세대1주택","주택") -> 주택 | AH33: =AH10 -> 주택 | AI33: =AI10 -> 주택 | AJ33: =AJ10 -> 주택 | AK33: =AK10 -> 주택 | AL33: =IF(OR($B$5="1세대1주택"),"1세대1주택","주택") -> 주택
A34: 소유자1 | B34: =IF($B$6=B$9,"거주","") -> 거주 | C34: =IF($B$6=C$9,"거주","") | D34: =IF($B$6=D$9,"거주","") | E34: =IF($B$6=E$9,"거주","") | F34: =B34 -> 거주 | I34: 소유자1의 거주지 | J34: =IF($B$6=J$9,"거주","") -> 거주 | K34: =IF($B$6=K$9,"거주","") | L34: =IF($B$6=L$9,"거주","") | M34: =IF($B$6=M$9,"거주","") | N34: =J34 -> 거주 | Q34: 소유자1 거주지 | R34: =IF($B$6=R$9,"거주","") -> 거주 | S34: =IF($B$6=S$9,"거주","") | T34: =IF($B$6=T$9,"거주","") | U34: =IF($B$6=U$9,"거주","") | V34: =R34 -> 거주 | Y34: 소유자1 거주지 | Z34: =IF($B$6=Z$9,"거주","") -> 거주 | AA34: =IF($B$6=AA$9,"거주","") | AB34: =IF($B$6=AB$9,"거주","") | AC34: =IF($B$6=AC$9,"거주","") | AD34: =Z34 -> 거주 | AG34: 소유자1 거주지 | AH34: =IF($B$6=AH$9,"거주","") -> 거주 | AI34: =IF($B$6=AI$9,"거주","") | AJ34: =IF($B$6=AJ$9,"거주","") | AK34: =IF($B$6=AK$9,"거주","") | AL34: =AH34 -> 거주
A35: 보유지분 | B35: =HLOOKUP(B$9,기초!$C$5:$I$16,MATCH($A35,기초!$A$5:$A$16,0),0) -> 1 | C35: =HLOOKUP(C$9,기초!$C$5:$I$16,MATCH($A35,기초!$A$5:$A$16,0),0) -> 0.5 | D35: =HLOOKUP(D$9,기초!$C$5:$I$16,MATCH($A35,기초!$A$5:$A$16,0),0) -> 1 | E35: =HLOOKUP(E$9,기초!$C$5:$I$16,MATCH($A35,기초!$A$5:$A$16,0),0) -> 1 | I35: 보유지분 | J35: =B35 -> 1 | K35: =C35 -> 0.5 | L35: =D35 -> 1 | M35: =E35 -> 1 | Q35: 소유지분(%) | R35: =J35 -> 1 | S35: =K35 -> 0.5 | T35: =L35 -> 1 | U35: =M35 -> 1 | Y35: 소유지분(%) | Z35: =R35 -> 1 | AA35: =S35 -> 0.5 | AB35: =T35 -> 1 | AC35: =U35 -> 1 | AG35: 소유지분(%) | AH35: =Z35 -> 1 | AI35: =AA35 -> 0.5 | AJ35: =AB35 -> 1 | AK35: =AC35 -> 1
A36: 보유기간 | B36: =HLOOKUP(B$9,기초!$C$5:$I$16,MATCH($A36,기초!$A$5:$A$16,0),0) -> 15 | C36: =HLOOKUP(C$9,기초!$C$5:$I$16,MATCH($A36,기초!$A$5:$A$16,0),0) -> 4 | D36: =HLOOKUP(D$9,기초!$C$5:$I$16,MATCH($A36,기초!$A$5:$A$16,0),0) -> 5 | E36: =HLOOKUP(E$9,기초!$C$5:$I$16,MATCH($A36,기초!$A$5:$A$16,0),0) -> 6 | F36: =IF(F33="1세대1주택",B36-1,) -> 0 | I36: 보유기간(연) | J36: =B36+1 -> 16 | K36: =C36+1 -> 5 | L36: =D36+1 -> 6 | M36: =E36+1 -> 7 | N36: =IF(N33="1세대1주택",J36-1,) -> 0
A37: 보유공제 | B37: =IF(B33="1세대1주택",IF(B36>=15,50%,IF(B36>=10,40%,IF(B36>=5,20%,0)))) -> FALSE | C37: =IF(C33="1세대1주택",IF(C36>=15,50%,IF(C36>=10,40%,IF(C36>=5,20%,0)))) -> FALSE | D37: =IF(D33="1세대1주택",IF(D36>=15,50%,IF(D36>=10,40%,IF(D36>=5,20%,0)))) -> FALSE | E37: =IF(E33="1세대1주택",IF(E36>=15,50%,IF(E36>=10,40%,IF(E36>=5,20%,0)))) -> FALSE | F37: =IF(F33="1세대1주택",IF(F36>=15,50%,IF(F36>=10,40%,IF(F36>=5,20%,0)))) -> FALSE | I37: 보유공제(%) | J37: =IF(J$33="1세대1주택",IF(J36>=15,25%,IF(J36>=10,20%,IF(J36>=5,10%,0)))) -> FALSE | K37: =IF(K$33="1세대1주택",IF(K36>=15,25%,IF(K36>=10,20%,IF(K36>=5,10%,0)))) -> FALSE | L37: =IF(L$33="1세대1주택",IF(L36>=15,25%,IF(L36>=10,20%,IF(L36>=5,10%,0)))) -> FALSE | M37: =IF(M$33="1세대1주택",IF(M36>=15,25%,IF(M36>=10,20%,IF(M36>=5,10%,0)))) -> FALSE | N37: =IF(N$33="1세대1주택",IF(N36>=15,25%,IF(N36>=10,20%,IF(N36>=5,10%,0)))) -> FALSE
A38: 주택수 | B38: =$B$3 -> 4 | I38: 주택수 | J38: =$B$3 -> 4 | Q38: 주택수 | R38: =$B$3 -> 4 | Y38: 주택수 | Z38: =$B$3 -> 4 | AG38: 주택수 | AH38: =$B$3 -> 4
A39: 적용세율 | B39: =IF(B38<=2,"기본세율","중과세율") -> 중과세율
I40: 거주기간 | J40: 15 | K40: 1 | L40: 2 | M40: 3 | N40: =OFFSET($I$40,0,MATCH("거주",$J34:$M34,0)) -> 15 | Q40: 거주기간(연) | R40: =IF(R34="거주",J40+1,J40) -> 16 | S40: =IF(S34="거주",K40+1,K40) -> 1 | T40: =IF(T34="거주",L40+1,L40) -> 2 | U40: =IF(U34="거주",M40+1,M40) -> 3 | V40: =OFFSET($I$40,0,MATCH("거주",$J34:$M34,0)) -> 15 | Y40: 거주기간(연) | Z40: =IF(Z34="거주",R40+1,R40) -> 17 | AA40: =IF(AA34="거주",S40+1,S40) -> 1 | AB40: =IF(AB34="거주",T40+1,T40) -> 2 | AC40: =IF(AC34="거주",U40+1,U40) -> 3 | AD40: =IF(AD34="거주",V40+1,V40) -> 16 | AG40: 거주기간(연) | AH40: =IF(AH34="거주",Z40+1,Z40) -> 18 | AI40: =IF(AI34="거주",AA40+1,AA40) -> 1 | AJ40: =IF(AJ34="거주",AB40+1,AB40) -> 2 | AK40: =IF(AK34="거주",AC40+1,AC40) -> 3 | AL40: =IF(AL34="거주",AD40+1,AD40) -> 17
I41: 거주공제(%) | J41: =IF(AND(J33="1세대1주택",COUNTIF($J$34:$J$34,"거주")=1),IF(J40>=15,50%,IF(J40>=10,40%,IF(J40>=5,20%,0)))) -> FALSE | K41: =IF(AND(K33="1세대1주택",COUNTIF($J$34:$J$34,"거주")=1),IF(K40>=15,50%,IF(K40>=10,40%,IF(K40>=5,20%,0)))) -> FALSE | L41: =IF(AND(L33="1세대1주택",COUNTIF($J$34:$J$34,"거주")=1),IF(L40>=15,50%,IF(L40>=10,40%,IF(L40>=5,20%,0)))) -> FALSE | M41: =IF(AND(M33="1세대1주택",COUNTIF($J$34:$J$34,"거주")=1),IF(M40>=15,50%,IF(M40>=10,40%,IF(M40>=5,20%,0)))) -> FALSE | N41: =IF(AND(N33="1세대1주택",COUNTIF($J$34:$J$34,"거주")=1),IF(N40>=15,50%,IF(N40>=10,40%,IF(N40>=5,20%,0)))) -> FALSE | Q41: 거주공제(%) | R41: =IF(AND(R33="1세대1주택",COUNTIF($J$34:$J$34,"거주")=1),IF(R40>=15,50%,IF(R40>=10,40%,IF(R40>=5,20%,0)))) -> FALSE | S41: =IF(AND(S33="1세대1주택",COUNTIF($J$34:$J$34,"거주")=1),IF(S40>=15,50%,IF(S40>=10,40%,IF(S40>=5,20%,0)))) -> FALSE | T41: =IF(AND(T33="1세대1주택",COUNTIF($J$34:$J$34,"거주")=1),IF(T40>=15,50%,IF(T40>=10,40%,IF(T40>=5,20%,0)))) -> FALSE | U41: =IF(AND(U33="1세대1주택",COUNTIF($J$34:$J$34,"거주")=1),IF(U40>=15,50%,IF(U40>=10,40%,IF(U40>=5,20%,0)))) -> FALSE | V41: =IF(AND(V33="1세대1주택",COUNTIF($J$34:$J$34,"거주")=1),IF(V40>=15,50%,IF(V40>=10,40%,IF(V40>=5,20%,0)))) -> FALSE | Y41: 거주공제(%) | Z41: =IF(AND(Z33="1세대1주택",COUNTIF($J$34:$J$34,"거주")=1),IF(Z40>=15,50%,IF(Z40>=10,40%,IF(Z40>=5,20%,0)))) -> FALSE | AA41: =IF(AND(AA33="1세대1주택",COUNTIF($J$34:$J$34,"거주")=1),IF(AA40>=15,50%,IF(AA40>=10,40%,IF(AA40>=5,20%,0)))) -> FALSE | AB41: =IF(AND(AB33="1세대1주택",COUNTIF($J$34:$J$34,"거주")=1),IF(AB40>=15,50%,IF(AB40>=10,40%,IF(AB40>=5,20%,0)))) -> FALSE | AC41: =IF(AND(AC33="1세대1주택",COUNTIF($J$34:$J$34,"거주")=1),IF(AC40>=15,50%,IF(AC40>=10,40%,IF(AC40>=5,20%,0)))) -> FALSE | AD41: =IF(AND(AD33="1세대1주택",COUNTIF($Z$34:$Z$34,"거주")=1),IF(AD40>=15,50%,IF(AD40>=10,40%,IF(AD40>=5,20%,0)))) -> FALSE | AG41: 거주공제(%) | AH41: =IF(AND(AH33="1세대1주택",COUNTIF($J$34:$J$34,"거주")=1),IF(AH40>=15,50%,IF(AH40>=10,40%,IF(AH40>=5,20%,0)))) -> FALSE | AI41: =IF(AND(AI33="1세대1주택",COUNTIF($J$34:$J$34,"거주")=1),IF(AI40>=15,50%,IF(AI40>=10,40%,IF(AI40>=5,20%,0)))) -> FALSE | AJ41: =IF(AND(AJ33="1세대1주택",COUNTIF($J$34:$J$34,"거주")=1),IF(AJ40>=15,50%,IF(AJ40>=10,40%,IF(AJ40>=5,20%,0)))) -> FALSE | AK41: =IF(AND(AK33="1세대1주택",COUNTIF($J$34:$J$34,"거주")=1),IF(AK40>=15,50%,IF(AK40>=10,40%,IF(AK40>=5,20%,0)))) -> FALSE | AL41: =IF(AND(AL33="1세대1주택",COUNTIF($Z$34:$Z$34,"거주")=1),IF(AL40>=15,50%,IF(AL40>=10,40%,IF(AL40>=5,20%,0)))) -> FALSE
A42: 연령 | B42: 66 | F42: =B42-1 -> 65 | I42: 연령(세) | J42: =B42+1 -> 67 | N42: =J42-1 -> 66 | Q42: 연령(세) | R42: =J42+1 -> 68 | V42: =R42-1 -> 67 | Y42: 연령(세) | Z42: =R42+1 -> 69 | AD42: =Z42-1 -> 68 | AG42: 연령(세) | AH42: =Z42+1 -> 70 | AL42: =AH42-1 -> 69
A43: 연령공제 | B43: =IF(B33="1세대1주택",IF(B42>=70,40%,IF(B42>=65,30%,IF(B42>=60,20%,0)))) -> FALSE | F43: =IF(F33="1세대1주택",IF(F42>=70,40%,IF(F42>=65,30%,IF(F42>=60,20%,0)))) -> FALSE | I43: 연령공제(%) | J43: =IF(J33="1세대1주택",IF(J42>=70,40%,IF(J42>=65,30%,IF(J42>=60,20%,0)))) -> FALSE | N43: =IF(N33="1세대1주택",IF(N42>=70,40%,IF(N42>=65,30%,IF(N42>=60,20%,0)))) -> FALSE | Q43: 연령공제(%) | R43: =IF(R33="1세대1주택",IF(R42>=70,40%,IF(R42>=65,30%,IF(R42>=60,20%,0)))) -> FALSE | V43: =IF(V33="1세대1주택",IF(V42>=70,40%,IF(V42>=65,30%,IF(V42>=60,20%,0)))) -> FALSE | Y43: 연령공제(%) | Z43: =IF(Z33="1세대1주택",IF(Z42>=70,40%,IF(Z42>=65,30%,IF(Z42>=60,20%,0)))) -> FALSE | AD43: =IF(AD33="1세대1주택",IF(AD42>=70,40%,IF(AD42>=65,30%,IF(AD42>=60,20%,0)))) -> FALSE | AG43: 연령공제(%) | AH43: =IF(AH33="1세대1주택",IF(AH42>=70,40%,IF(AH42>=65,30%,IF(AH42>=60,20%,0)))) -> FALSE | AL43: =IF(AL33="1세대1주택",IF(AL42>=70,40%,IF(AL42>=65,30%,IF(AL42>=60,20%,0)))) -> FALSE
A44: 세액공제율 | B44: =IF(B33="1세대1주택",MIN(80%,SUM(B43,B37)),0) -> 0 | F44: =IF(F33="1세대1주택",MIN(80%,SUM(F43,F37)),0) -> 0 | I44: 세액공제율 | J44: =IF(J33="1세대1주택",MIN(80%,J$43+MAX(J$41,J$37)),0) -> 0 | N44: =IF(N33="1세대1주택",MIN(80%,N$43+MAX(N$41,N$37)),0) -> 0 | Q44: 세액공제율 | R44: =IF(R33="1세대1주택",MIN(80%,R$43+MAX(R$41,R$37)),0) -> 0 | V44: =IF(V33="1세대1주택",MIN(80%,V$43+MAX(V$41,V$37)),0) -> 0 | Y44: 세액공제율 | Z44: =IF(Z33="1세대1주택",MIN(80%,Z$43+MAX(Z$41,Z$37)),0) -> 0 | AD44: =IF(AD33="1세대1주택",MIN(80%,AD41+AD43)) -> FALSE | AG44: 세액공제율 | AH44: =IF(AH33="1세대1주택",MIN(80%,AH$43+MAX(AH$41,AH$37)),0) -> 0 | AL44: =IF(AL33="1세대1주택",MIN(80%,AL41+AL43)) -> FALSE
...

Sheet 단독보유(부부특례)
B1: 소유자1
A2: 소유자 | B2: =기초!$B$1 -> 홍길동
A3: 주택수 | B3: 4 | E3: 2026 | M3: =E3+1 -> 2027 | U3: =M3+1 -> 2028 | AC3: =U3+1 -> 2029 | AK3: =AC3+1 -> 2030
A4: 개정세법 분류 | B4: =IF(AND(B5="1세대1주택",LEFT(B6,2)="주택"),"거주용1주택",IF(AND(B5="1세대1주택",B6="비거주"),"비거주1주택",IF(AND(B3<=2,B7<>"조정대상지역"),"비거주1주택","3주택"))) -> 3주택 | E4: 재산세납부액 | F4: =SUM(B20:G20) -> 24722550 | M4: 재산세납부액 | N4: =SUM(J20:O20) -> 31102582 | U4: 재산세납부액 | V4: =SUM(R20:W20) -> 34087650 | AC4: 재산세납부액 | AD4: =SUM(Z20:AE20) -> 36221570 | AK4: 재산세납부액 | AL4: =SUM(AH20:AM20) -> 41478376
A5: 1세대1주택 여부 | B5: 해당없음 | E5: 종부세납부액 | F5: =B61 -> 98761830 | M5: 종부세납부액 | N5: =HLOOKUP($B$4,$J$46:$L$61,16,0) -> 1.7295513e+08 | U5: 종부세납부액 | V5: =HLOOKUP($B$4,$R$46:$T$61,16,0) -> 2.1102175e+08 | AC5: 종부세납부액 | AD5: =HLOOKUP($B$4,$Z$46:$AB$61,16,0) -> 2.6338335e+08 | AK5: 종부세납부액 | AL5: =HLOOKUP($B$4,$AH$46:$AJ$61,16,0) -> 2.8658306e+08
A6: 거주주택 | B6: 주택1 | E6: 소계 | F6: =F4+F5 -> 1.2348438e+08 | M6: 보유세 합계 | N6: =N4+N5 -> 2.0405771e+08 | U6: 보유세 합계 | V6: =V4+V5 -> 2.451094e+08 | AC6: 보유세 합계 | AD6: =AD4+AD5 -> 2.9960492e+08 | AK6: 보유세 합계 | AL6: =AL4+AL5 -> 3.2806144e+08
A7: 지역 | B7: =HLOOKUP(B$6,기초!$C$5:$I$16,MATCH($A7,기초!$A$5:$A$16,0),0) -> 조정대상지역
I8: 예상증가율(%) | J8: 0.15 | K8: 0.15 | L8: 0.15 | M8: 0.15 | O8: 0 | Q8: 예상증가율(%) | R8: 0 | S8: 0 | T8: 0 | U8: 0 | W8: 0 | Y8: 예상증가율(%) | Z8: 0.15 | AA8: 0.15 | AB8: 0.15 | AC8: 0.15 | AE8: 0.15 | AG8: 예상증가율(%) | AH8: 0.1 | AI8: 0.01 | AJ8: 0.03 | AK8: 0.05 | AM8: 0.15
A9: 2026 | B9: 주택1 | C9: 주택2 | D9: 주택3 | E9: 주택4 | F9: 주택소계 | G9: 건축물 | I9: =A9+1 -> 2027 | J9: 주택1 | K9: 주택2 | L9: 주택3 | M9: 주택4 | N9: 주택소계 | O9: 건축물 | Q9: =I9+1 -> 2028 | R9: 주택1 | S9: 주택2 | T9: 주택3 | U9: 주택4 | V9: 주택소계 | W9: 건축물 | Y9: =Q9+1 -> 2029 | Z9: 주택1 | AA9: 주택2 | AB9: 주택3 | AC9: 주택4 | AD9: 주택소계 | AE9: 건축물 | AG9: =Y9+1 -> 2030 | AH9: 주택1 | AI9: 주택2 | AJ9: 주택3 | AK9: 주택4 | AL9: 주택소계 | AM9: 건축물
B10: =IF(OR($B$5="1세대1주택"),"1세대1주택","주택") -> 주택 | C10: =IF(OR($B$5="1세대1주택"),"1세대1주택","주택") -> 주택 | D10: =IF(OR($B$5="1세대1주택"),"1세대1주택","주택") -> 주택 | E10: =IF(OR($B$5="1세대1주택"),"1세대1주택","주택") -> 주택 | F10: 주택 | G10: 건물 | J10: =B$10 -> 주택 | K10: =C$10 -> 주택 | L10: =D$10 -> 주택 | M10: =E$10 -> 주택 | N10: 주택 | O10: 건물 | R10: =J$10 -> 주택 | S10: =K$10 -> 주택 | T10: =L$10 -> 주택 | U10: =M$10 -> 주택 | V10: 주택 | W10: 건물 | Z10: =R$10 -> 주택 | AA10: =S$10 -> 주택 | AB10: =T$10 -> 주택 | AC10: =U$10 -> 주택 | AD10: 주택 | AE10: 건물 | AH10: =Z$10 -> 주택 | AI10: =AA$10 -> 주택 | AJ10: =AB$10 -> 주택 | AK10: =AC$10 -> 주택 | AL10: 주택 | AM10: 건물
A11: 시가표준액 | B11: =HLOOKUP(B$9,기초!$C$5:$I$16,MATCH($A11,기초!$A$5:$A$16,0),0) -> 3500000000 | C11: =HLOOKUP(C$9,기초!$C$5:$I$16,MATCH($A11,기초!$A$5:$A$16,0),0) -> 1150000000 | D11: =HLOOKUP(D$9,기초!$C$5:$I$16,MATCH($A11,기초!$A$5:$A$16,0),0) -> 1.725e+09 | E11: =HLOOKUP(E$9,기초!$C$5:$I$16,MATCH($A11,기초!$A$5:$A$16,0),0) -> 2300000000 | F11: =SUM(B11:E11) -> 8675000000 | G11: =HLOOKUP(G$9,[1]기초!$C$5:$I$16,MATCH($A11,[1]기초!$A$5:$A$16,0),0) -> 0 | I11: 시가표준액(예상) | J11: =B11*(1+J8) -> 4.025e+09 | K11: =C11*(1+K8) -> 1322500000 | L11: =D11*(1+L8) -> 1.98375e+09 | M11: =E11*(1+M8) -> 2645000000 | N11: =SUM(J11:M11) -> 9976250000 | O11: =G11*(1+O8) -> 0 | Q11: 시가표준액(예상) | R11: =J11*(1+R8) -> 4.025e+09 | S11: =K11*(1+S8) -> 1322500000 | T11: =L11*(1+T8) -> 1.98375e+09 | U11: =M11*(1+U8) -> 2645000000 | V11: =SUM(R11:U11) -> 9976250000 | W11: =O11*(1+W8) -> 0 | Y11: 시가표준액(예상) | Z11: =R11*(1+Z8) -> 4.62875e+09 | AA11: =S11*(1+AA8) -> 1520875000 | AB11: =T11*(1+AB8) -> 2.2813125e+09 | AC11: =U11*(1+AC8) -> 3041750000 | AD11: =SUM(Z11:AC11) -> 1.1472687e+10 | AE11: =W11*(1+AE8) -> 0 | AG11: 시가표준액(예상) | AH11: =Z11*(1+AH8) -> 5.091625e+09 | AI11: =AA11*(1+AI8) -> 1536083750 | AJ11: =AB11*(1+AJ8) -> 2.3497519e+09 | AK11: =AC11*(1+AK8) -> 3193837500 | AL11: =SUM(AH11:AK11) -> 1.2171298e+10 | AM11: =AE11*(1+AM8) -> 0
A12: 공정시장가액비율 | B12: =IF(B$10="1세대1주택", IF(B11<=3*10^8,43%, IF(B11<=6*10^8,44%, 45%)), VLOOKUP(B$10,t!$H$3:$I$9,2,0)) -> 0.6 | C12: =IF(C$10="1세대1주택", IF(C11<=3*10^8,43%, IF(C11<=6*10^8,44%, 45%)), VLOOKUP(C$10,t!$H$3:$I$9,2,0)) -> 0.6 | D12: =IF(D$10="1세대1주택", IF(D11<=3*10^8,43%, IF(D11<=6*10^8,44%, 45%)), VLOOKUP(D$10,t!$H$3:$I$9,2,0)) -> 0.6 | E12: =IF(E$10="1세대1주택", IF(E11<=3*10^8,43%, IF(E11<=6*10^8,44%, 45%)), VLOOKUP(E$10,t!$H$3:$I$9,2,0)) -> 0.6 | F12: =IF(B10="1세대1주택",B12,60%) -> 0.6 | G12: =IF(G10="1세대1주택", IF(G11<=3*10^8,43%, IF(G11<=6*10^8,44%, 45%)), VLOOKUP(G10,t!$H$3:$I$9,2,0)) -> 0.7 | I12: 공정시장가액비율 | J12: =IF(J$10="1세대1주택", IF(J11<=3*10^8,43%, IF(J11<=6*10^8,44%, 45%)), VLOOKUP(J$10,t!$H$3:$I$9,2,0)) -> 0.6 | K12: =IF(K$10="1세대1주택", IF(K11<=3*10^8,43%, IF(K11<=6*10^8,44%, 45%)), VLOOKUP(K$10,t!$H$3:$I$9,2,0)) -> 0.6 | L12: =IF(L$10="1세대1주택", IF(L11<=3*10^8,43%, IF(L11<=6*10^8,44%, 45%)), VLOOKUP(L$10,t!$H$3:$I$9,2,0)) -> 0.6 | M12: =IF(M$10="1세대1주택", IF(M11<=3*10^8,43%, IF(M11<=6*10^8,44%, 45%)), VLOOKUP(M$10,t!$H$3:$I$9,2,0)) -> 0.6 | N12: =IF(J10="1세대1주택",J12,60%) -> 0.6 | O12: =IF(O10="1세대1주택", IF(O11<=3*10^8,43%, IF(O11<=6*10^8,44%, 45%)), VLOOKUP(O10,t!$H$3:$I$9,2,0)) -> 0.7 | Q12: 공정시장가액비율 | R12: =IF(R$10="1세대1주택", IF(R11<=3*10^8,43%, IF(R11<=6*10^8,44%, 45%)), VLOOKUP(R$10,t!$H$3:$I$9,2,0)) -> 0.6 | S12: =IF(S$10="1세대1주택", IF(S11<=3*10^8,43%, IF(S11<=6*10^8,44%, 45%)), VLOOKUP(S$10,t!$H$3:$I$9,2,0)) -> 0.6 | T12: =IF(T$10="1세대1주택", IF(T11<=3*10^8,43%, IF(T11<=6*10^8,44%, 45%)), VLOOKUP(T$10,t!$H$3:$I$9,2,0)) -> 0.6 | U12: =IF(U$10="1세대1주택", IF(U11<=3*10^8,43%, IF(U11<=6*10^8,44%, 45%)), VLOOKUP(U$10,t!$H$3:$I$9,2,0)) -> 0.6 | V12: =IF(R10="1세대1주택",R12,60%) -> 0.6 | W12: =IF(W10="1세대1주택", IF(W11<=3*10^8,43%, IF(W11<=6*10^8,44%, 45%)), VLOOKUP(W10,t!$H$3:$I$9,2,0)) -> 0.7 | Y12: 공정시장가액비율 | Z12: =IF(Z$10="1세대1주택", IF(Z11<=3*10^8,43%, IF(Z11<=6*10^8,44%, 45%)), VLOOKUP(Z$10,t!$H$3:$I$9,2,0)) -> 0.6 | AA12: =IF(AA$10="1세대1주택", IF(AA11<=3*10^8,43%, IF(AA11<=6*10^8,44%, 45%)), VLOOKUP(AA$10,t!$H$3:$I$9,2,0)) -> 0.6 | AB12: =IF(AB$10="1세대1주택", IF(AB11<=3*10^8,43%, IF(AB11<=6*10^8,44%, 45%)), VLOOKUP(AB$10,t!$H$3:$I$9,2,0)) -> 0.6 | AC12: =IF(AC$10="1세대1주택", IF(AC11<=3*10^8,43%, IF(AC11<=6*10^8,44%, 45%)), VLOOKUP(AC$10,t!$H$3:$I$9,2,0)) -> 0.6 | AD12: =IF(Z10="1세대1주택",Z12,60%) -> 0.6 | AE12: =IF(AE10="1세대1주택", IF(AE11<=3*10^8,43%, IF(AE11<=6*10^8,44%, 45%)), VLOOKUP(AE10,t!$H$3:$I$9,2,0)) -> 0.7 | AG12: 공정시장가액비율 | AH12: =IF(AH$10="1세대1주택", IF(AH11<=3*10^8,43%, IF(AH11<=6*10^8,44%, 45%)), VLOOKUP(AH$10,t!$H$3:$I$9,2,0)) -> 0.6 | AI12: =IF(AI$10="1세대1주택", IF(AI11<=3*10^8,43%, IF(AI11<=6*10^8,44%, 45%)), VLOOKUP(AI$10,t!$H$3:$I$9,2,0)) -> 0.6 | AJ12: =IF(AJ$10="1세대1주택", IF(AJ11<=3*10^8,43%, IF(AJ11<=6*10^8,44%, 45%)), VLOOKUP(AJ$10,t!$H$3:$I$9,2,0)) -> 0.6 | AK12: =IF(AK$10="1세대1주택", IF(AK11<=3*10^8,43%, IF(AK11<=6*10^8,44%, 45%)), VLOOKUP(AK$10,t!$H$3:$I$9,2,0)) -> 0.6 | AL12: =IF(AH10="1세대1주택",AH12,60%) -> 0.6 | AM12: =IF(AM10="1세대1주택", IF(AM11<=3*10^8,43%, IF(AM11<=6*10^8,44%, 45%)), VLOOKUP(AM10,t!$H$3:$I$9,2,0)) -> 0.7
A13: 과세표준(주택상한) | B13: =IF(RIGHT(B10,2)="주택",MIN(B11*B12,B23*B12+B11*B12*5%),B11*B12) -> 2100000000 | C13: =IF(RIGHT(C10,2)="주택",MIN(C11*C12,C23*C12+C11*C12*5%),C11*C12) -> 514500000 | D13: =IF(RIGHT(D10,2)="주택",MIN(D11*D12,D23*D12+D11*D12*5%),D11*D12) -> 771750000 | E13: =IF(RIGHT(E10,2)="주택",MIN(E11*E12,E23*E12+E11*E12*5%),E11*E12) -> 1089000000 | F13: =F11*F12 -> 5205000000 | G13: =IF(RIGHT(G10,2)="주택",MIN(G11*G12,G24*G12+G11*G12*5%),G11*G12) -> 0 | I13: 재산세 과세표준 | J13: =IF(RIGHT(J10,2)="주택",MIN(J11*J12,J23*J12+J11*J12*5%),J11*J12) -> 2220750000 | K13: =IF(RIGHT(K10,2)="주택",MIN(K11*K12,K23*K12+K11*K12*5%),K11*K12) -> 729675000 | L13: =IF(RIGHT(L10,2)="주택",MIN(L11*L12,L23*L12+L11*L12*5%),L11*L12) -> 1.0945125e+09 | M13: =IF(RIGHT(M10,2)="주택",MIN(M11*M12,M23*M12+M11*M12*5%),M11*M12) -> 1459350000 | N13: =N11*N12 -> 5985750000 | O13: =IF(RIGHT(O10,2)="주택",MIN(O11*O12,O23*O12+O11*O12*5%),O11*O12) -> 0 | Q13: 재산세 과세표준 | R13: =IF(RIGHT(R10,2)="주택",MIN(R11*R12,R23*R12+R11*R12*5%),R11*R12) -> 2.415e+09 | S13: =IF(RIGHT(S10,2)="주택",MIN(S11*S12,S23*S12+S11*S12*5%),S11*S12) -> 793500000 | T13: =IF(RIGHT(T10,2)="주택",MIN(T11*T12,T23*T12+T11*T12*5%),T11*T12) -> 1.19025e+09 | U13: =IF(RIGHT(U10,2)="주택",MIN(U11*U12,U23*U12+U11*U12*5%),U11*U12) -> 1587000000 | V13: =V11*V12 -> 5985750000 | W13: =IF(RIGHT(W10,2)="주택",MIN(W11*W12,W23*W12+W11*W12*5%),W11*W12) -> 0 | Y13: 재산세 과세표준 | Z13: =IF(RIGHT(Z10,2)="주택",MIN(Z11*Z12,Z23*Z12+Z11*Z12*5%),Z11*Z12) -> 2.5538625e+09 | AA13: =IF(RIGHT(AA10,2)="주택",MIN(AA11*AA12,AA23*AA12+AA11*AA12*5%),AA11*AA12) -> 839126250 | AB13: =IF(RIGHT(AB10,2)="주택",MIN(AB11*AB12,AB23*AB12+AB11*AB12*5%),AB11*AB12) -> 1.2586894e+09 | AC13: =IF(RIGHT(AC10,2)="주택",MIN(AC11*AC12,AC23*AC12+AC11*AC12*5%),AC11*AC12) -> 1678252500 | AD13: =AD11*AD12 -> 6.8836125e+09 | AE13: =IF(RIGHT(AE10,2)="주택",MIN(AE11*AE12,AE23*AE12+AE11*AE12*5%),AE11*AE12) -> 0 | AG13: 재산세 과세표준 | AH13: =IF(RIGHT(AH10,2)="주택",MIN(AH11*AH12,AH23*AH12+AH11*AH12*5%),AH11*AH12) -> 2.9299987e+09 | AI13: =IF(RIGHT(AI10,2)="주택",MIN(AI11*AI12,AI23*AI12+AI11*AI12*5%),AI11*AI12) -> 921650250 | AJ13: =IF(RIGHT(AJ10,2)="주택",MIN(AJ11*AJ12,AJ23*AJ12+AJ11*AJ12*5%),AJ11*AJ12) -> 1.4098511e+09 | AK13: =IF(RIGHT(AK10,2)="주택",MIN(AK11*AK12,AK23*AK12+AK11*AK12*5%),AK11*AK12) -> 1916302500 | AL13: =AL11*AL12 -> 7.3027789e+09 | AM13: =IF(RIGHT(AM10,2)="주택",MIN(AM11*AM12,AM23*AM12+AM11*AM12*5%),AM11*AM12) -> 0
A14: t | B14: {=IF(AND(B10="1세대1주택",B11<=9*10^8),INDEX(t!$D$3:$D$6,MATCH(TRUE,B13<=t!$A$3:$A$6,0)),INDEX(t!$B$3:$B$6,MATCH(TRUE,B13<=t!$A$3:$A$6,0)))} -> 0.004 | C14: {=IF(AND(C10="1세대1주택",C11<=9*10^8),INDEX(t!$D$3:$D$6,MATCH(TRUE,C13<=t!$A$3:$A$6,0)),INDEX(t!$B$3:$B$6,MATCH(TRUE,C13<=t!$A$3:$A$6,0)))} -> 0.004 | D14: {=IF(AND(D10="1세대1주택",D11<=9*10^8),INDEX(t!$D$3:$D$6,MATCH(TRUE,D13<=t!$A$3:$A$6,0)),INDEX(t!$B$3:$B$6,MATCH(TRUE,D13<=t!$A$3:$A$6,0)))} -> 0.004 | E14: {=IF(AND(E10="1세대1주택",E11<=9*10^8),INDEX(t!$D$3:$D$6,MATCH(TRUE,E13<=t!$A$3:$A$6,0)),INDEX(t!$B$3:$B$6,MATCH(TRUE,E13<=t!$A$3:$A$6,0)))} -> 0.004 | F14: {=INDEX(t!$B$3:$B$6,MATCH(TRUE,F13<=t!$A$3:$A$6,0))} -> 0.004 | G14: 0.0025 | I14: t | J14: {=IF(AND(J10="1세대1주택",J11<=9*10^8),INDEX(t!$D$3:$D$6,MATCH(TRUE,J13<=t!$A$3:$A$6,0)),INDEX(t!$B$3:$B$6,MATCH(TRUE,J13<=t!$A$3:$A$6,0)))} -> 0.004 | K14: {=IF(AND(K10="1세대1주택",K11<=9*10^8),INDEX(t!$D$3:$D$6,MATCH(TRUE,K13<=t!$A$3:$A$6,0)),INDEX(t!$B$3:$B$6,MATCH(TRUE,K13<=t!$A$3:$A$6,0)))} -> 0.004 | L14: {=IF(AND(L10="1세대1주택",L11<=9*10^8),INDEX(t!$D$3:$D$6,MATCH(TRUE,L13<=t!$A$3:$A$6,0)),INDEX(t!$B$3:$B$6,MATCH(TRUE,L13<=t!$A$3:$A$6,0)))} -> 0.004 | M14: {=IF(AND(M10="1세대1주택",M11<=9*10^8),INDEX(t!$D$3:$D$6,MATCH(TRUE,M13<=t!$A$3:$A$6,0)),INDEX(t!$B$3:$B$6,MATCH(TRUE,M13<=t!$A$3:$A$6,0)))} -> 0.004 | N14: {=INDEX(t!$B$3:$B$6,MATCH(TRUE,N13<=t!$A$3:$A$6,0))} -> 0.004 | O14: 0.0025 | Q14: t | R14: {=IF(AND(R10="1세대1주택",R11<=9*10^8),INDEX(t!$D$3:$D$6,MATCH(TRUE,R13<=t!$A$3:$A$6,0)),INDEX(t!$B$3:$B$6,MATCH(TRUE,R13<=t!$A$3:$A$6,0)))} -> 0.004 | S14: {=IF(AND(S10="1세대1주택",S11<=9*10^8),INDEX(t!$D$3:$D$6,MATCH(TRUE,S13<=t!$A$3:$A$6,0)),INDEX(t!$B$3:$B$6,MATCH(TRUE,S13<=t!$A$3:$A$6,0)))} -> 0.004 | T14: {=IF(AND(T10="1세대1주택",T11<=9*10^8),INDEX(t!$D$3:$D$6,MATCH(TRUE,T13<=t!$A$3:$A$6,0)),INDEX(t!$B$3:$B$6,MATCH(TRUE,T13<=t!$A$3:$A$6,0)))} -> 0.004 | U14: {=IF(AND(U10="1세대1주택",U11<=9*10^8),INDEX(t!$D$3:$D$6,MATCH(TRUE,U13<=t!$A$3:$A$6,0)),INDEX(t!$B$3:$B$6,MATCH(TRUE,U13<=t!$A$3:$A$6,0)))} -> 0.004 | V14: {=INDEX(t!$B$3:$B$6,MATCH(TRUE,V13<=t!$A$3:$A$6,0))} -> 0.004 | W14: 0.0025 | Y14: t | Z14: {=IF(AND(Z10="1세대1주택",Z11<=9*10^8),INDEX(t!$D$3:$D$6,MATCH(TRUE,Z13<=t!$A$3:$A$6,0)),INDEX(t!$B$3:$B$6,MATCH(TRUE,Z13<=t!$A$3:$A$6,0)))} -> 0.004 | AA14: {=IF(AND(AA10="1세대1주택",AA11<=9*10^8),INDEX(t!$D$3:$D$6,MATCH(TRUE,AA13<=t!$A$3:$A$6,0)),INDEX(t!$B$3:$B$6,MATCH(TRUE,AA13<=t!$A$3:$A$6,0)))} -> 0.004 | AB14: {=IF(AND(AB10="1세대1주택",AB11<=9*10^8),INDEX(t!$D$3:$D$6,MATCH(TRUE,AB13<=t!$A$3:$A$6,0)),INDEX(t!$B$3:$B$6,MATCH(TRUE,AB13<=t!$A$3:$A$6,0)))} -> 0.004 | AC14: {=IF(AND(AC10="1세대1주택",AC11<=9*10^8),INDEX(t!$D$3:$D$6,MATCH(TRUE,AC13<=t!$A$3:$A$6,0)),INDEX(t!$B$3:$B$6,MATCH(TRUE,AC13<=t!$A$3:$A$6,0)))} -> 0.004 | AD14: {=INDEX(t!$B$3:$B$6,MATCH(TRUE,AD13<=t!$A$3:$A$6,0))} -> 0.004 | AE14: 0.0025 | AG14: t | AH14: {=IF(AND(AH10="1세대1주택",AH11<=9*10^8),INDEX(t!$D$3:$D$6,MATCH(TRUE,AH13<=t!$A$3:$A$6,0)),INDEX(t!$B$3:$B$6,MATCH(TRUE,AH13<=t!$A$3:$A$6,0)))} -> 0.004 | AI14: {=IF(AND(AI10="1세대1주택",AI11<=9*10^8),INDEX(t!$D$3:$D$6,MATCH(TRUE,AI13<=t!$A$3:$A$6,0)),INDEX(t!$B$3:$B$6,MATCH(TRUE,AI13<=t!$A$3:$A$6,0)))} -> 0.004 | AJ14: {=IF(AND(AJ10="1세대1주택",AJ11<=9*10^8),INDEX(t!$D$3:$D$6,MATCH(TRUE,AJ13<=t!$A$3:$A$6,0)),INDEX(t!$B$3:$B$6,MATCH(TRUE,AJ13<=t!$A$3:$A$6,0)))} -> 0.004 | AK14: {=IF(AND(AK10="1세대1주택",AK11<=9*10^8),INDEX(t!$D$3:$D$6,MATCH(TRUE,AK13<=t!$A$3:$A$6,0)),INDEX(t!$B$3:$B$6,MATCH(TRUE,AK13<=t!$A$3:$A$6,0)))} -> 0.004 | AL14: {=INDEX(t!$B$3:$B$6,MATCH(TRUE,AL13<=t!$A$3:$A$6,0))} -> 0.004 | AM14: 0.0025
A15: 산출세액 | B15: =B13*B14-VLOOKUP(B14,IF(AND(B10="1세대1주택",B11<=9*10^8),t!$D$2:$E$6,t!$B$2:$C$6),2,0) -> 7770000 | C15: =C13*C14-VLOOKUP(C14,IF(AND(C10="1세대1주택",C11<=9*10^8),t!$D$2:$E$6,t!$B$2:$C$6),2,0) -> 1428000 | D15: =D13*D14-VLOOKUP(D14,IF(AND(D10="1세대1주택",D11<=9*10^8),t!$D$2:$E$6,t!$B$2:$C$6),2,0) -> 2457000 | E15: =E13*E14-VLOOKUP(E14,IF(AND(E10="1세대1주택",E11<=9*10^8),t!$D$2:$E$6,t!$B$2:$C$6),2,0) -> 3726000 | F15: =F13*F14-VLOOKUP(F14,t!$B$2:$C$6,2,0) -> 20190000 | G15: =G13*0.25% -> 0 | I15: 산출세액 | J15: =J13*J14-VLOOKUP(J14,IF(AND(J10="1세대1주택",J11<=9*10^8),t!$D$2:$E$6,t!$B$2:$C$6),2,0) -> 8253000 | K15: =K13*K14-VLOOKUP(K14,IF(AND(K10="1세대1주택",K11<=9*10^8),t!$D$2:$E$6,t!$B$2:$C$6),2,0) -> 2288700 | L15: =L13*L14-VLOOKUP(L14,IF(AND(L10="1세대1주택",L11<=9*10^8),t!$D$2:$E$6,t!$B$2:$C$6),2,0) -> 3748050 | M15: =M13*M14-VLOOKUP(M14,IF(AND(M10="1세대1주택",M11<=9*10^8),t!$D$2:$E$6,t!$B$2:$C$6),2,0) -> 5207400 | N15: =N13*N14-VLOOKUP(N14,t!$B$2:$C$6,2,0) -> 23313000 | O15: =O13*0.25% -> 0 | Q15: 산출세액 | R15: =R13*R14-VLOOKUP(R14,IF(AND(R10="1세대1주택",R11<=9*10^8),t!$D$2:$E$6,t!$B$2:$C$6),2,0) -> 9030000 | S15: =S13*S14-VLOOKUP(S14,IF(AND(S10="1세대1주택",S11<=9*10^8),t!$D$2:$E$6,t!$B$2:$C$6),2,0) -> 2544000 | T15: =T13*T14-VLOOKUP(T14,IF(AND(T10="1세대1주택",T11<=9*10^8),t!$D$2:$E$6,t!$B$2:$C$6),2,0) -> 4131000 | U15: =U13*U14-VLOOKUP(U14,IF(AND(U10="1세대1주택",U11<=9*10^8),t!$D$2:$E$6,t!$B$2:$C$6),2,0) -> 5718000 | V15: =V13*V14-VLOOKUP(V14,t!$B$2:$C$6,2,0) -> 23313000 | W15: =W13*0.25% -> 0 | Y15: 산출세액 | Z15: =Z13*Z14-VLOOKUP(Z14,IF(AND(Z10="1세대1주택",Z11<=9*10^8),t!$D$2:$E$6,t!$B$2:$C$6),2,0) -> 9585450 | AA15: =AA13*AA14-VLOOKUP(AA14,IF(AND(AA10="1세대1주택",AA11<=9*10^8),t!$D$2:$E$6,t!$B$2:$C$6),2,0) -> 2726505 | AB15: =AB13*AB14-VLOOKUP(AB14,IF(AND(AB10="1세대1주택",AB11<=9*10^8),t!$D$2:$E$6,t!$B$2:$C$6),2,0) -> 4404757.5 | AC15: =AC13*AC14-VLOOKUP(AC14,IF(AND(AC10="1세대1주택",AC11<=9*10^8),t!$D$2:$E$6,t!$B$2:$C$6),2,0) -> 6083010 | AD15: =AD13*AD14-VLOOKUP(AD14,t!$B$2:$C$6,2,0) -> 26904450 | AE15: =AE13*0.25% -> 0 | AG15: 산출세액 | AH15: =AH13*AH14-VLOOKUP(AH14,IF(AND(AH10="1세대1주택",AH11<=9*10^8),t!$D$2:$E$6,t!$B$2:$C$6),2,0) -> 11089995 | AI15: =AI13*AI14-VLOOKUP(AI14,IF(AND(AI10="1세대1주택",AI11<=9*10^8),t!$D$2:$E$6,t!$B$2:$C$6),2,0) -> 3056601 | AJ15: =AJ13*AJ14-VLOOKUP(AJ14,IF(AND(AJ10="1세대1주택",AJ11<=9*10^8),t!$D$2:$E$6,t!$B$2:$C$6),2,0) -> 5009404.5 | AK15: =AK13*AK14-VLOOKUP(AK14,IF(AND(AK10="1세대1주택",AK11<=9*10^8),t!$D$2:$E$6,t!$B$2:$C$6),2,0) -> 7035210 | AL15: =AL13*AL14-VLOOKUP(AL14,t!$B$2:$C$6,2,0) -> 28581115 | AM15: =AM13*0.25% -> 0
A16: 재산세액 | B16: =B15 -> 7770000 | C16: =C15 -> 1428000 | D16: =D15 -> 2457000 | E16: =E15 -> 3726000 | F16: =SUM(B16:E16) -> 15381000 | G16: =MIN(G15,F27*150%) -> 0 | I16: 재산세액 | J16: =J15 -> 8253000 | K16: =K15 -> 2288700 | L16: =L15 -> 3748050 | M16: =M15 -> 5207400 | N16: =SUM(J16:M16) -> 19497150 | O16: =MIN(O15,O27*150%) -> 0 | Q16: 재산세액 | R16: =R15 -> 9030000 | S16: =S15 -> 2544000 | T16: =T15 -> 4131000 | U16: =U15 -> 5718000 | V16: =SUM(R16:U16) -> 21423000 | W16: =MIN(W15,W27*150%) -> 0 | Y16: 재산세액 | Z16: =Z15 -> 9585450 | AA16: =AA15 -> 2726505 | AB16: =AB15 -> 4404757.5 | AC16: =AC15 -> 6083010 | AD16: =SUM(Z16:AC16) -> 22799722 | AE16: =MIN(AE15,AE27*150%) -> 0 | AG16: 재산세액 | AH16: =AH15 -> 11089995 | AI16: =AI15 -> 3056601 | AJ16: =AJ15 -> 5009404.5 | AK16: =AK15 -> 7035210 | AL16: =SUM(AH16:AK16) -> 26191210 | AM16: =MIN(AM15,AM27*150%) -> 0
A17: 도시지역분 | B17: =B$13*0.14% -> 2940000 | C17: =C$13*0.14% -> 720300 | D17: =D$13*0.14% -> 1080450 | E17: =E$13*0.14% -> 1524600 | G17: =G$13*0.14% -> 0 | I17: 도시지역분 | J17: =J$13*0.14% -> 3109050 | K17: =K$13*0.14% -> 1021545 | L17: =L$13*0.14% -> 1532317.5 | M17: =M$13*0.14% -> 2043090 | O17: =O$13*0.14% -> 0 | Q17: 도시지역분 | R17: =R$13*0.14% -> 3381000 | S17: =S$13*0.14% -> 1110900 | T17: =T$13*0.14% -> 1666350 | U17: =U$13*0.14% -> 2221800 | W17: =W$13*0.14% -> 0 | Y17: 도시지역분 | Z17: =Z$13*0.14% -> 3575407.5 | AA17: =AA$13*0.14% -> 1174776.8 | AB17: =AB$13*0.14% -> 1762165.1 | AC17: =AC$13*0.14% -> 2349553.5 | AE17: =AE$13*0.14% -> 0 | AG17: 도시지역분 | AH17: =AH$13*0.14% -> 4101998.2 | AI17: =AI$13*0.14% -> 1290310.4 | AJ17: =AJ$13*0.14% -> 1973791.6 | AK17: =AK$13*0.14% -> 2682823.5 | AM17: =AM$13*0.14% -> 0
